Workbook

Sheet Instructions
A1: Instructions:
A3: 1. Pick one of the orange tabs that has not been filled in already
A4: 2. Follow the instructions on that orange tab
A5: 3. Once all team members have filled their respective orange tabs, check the 'Team Availablity' tab
A6: and change the time zone value in that 'Team Availability' tab to your time zone to see team availability in your time zone

Sheet Lisa Zhou
A1: Step 1: Rename the sheet name with your name, for example 'Member 1 Name' to 'Your Name' | J1: Time Zone
A2: Step 2: Choose your time zone from yellow drop down box | J2: CST
A3: Step 3: Enter '1' in all 30-minute slots you're NOT available in orange area | J3: {=_xlfn.SWITCH(J2,"PST",0,"MST",1,"CST",2,"EST",3,0)} -> 2
A6: Time | B6: Monday | C6: Tuesday | D6: Wednesday | E6: Thursday | F6: Friday | G6: Saturday | H6: Sunday
A7: =TEXT(TIME(3,0,0)+$J$3/24,"h:mm AM/PM")&" - "&TEXT(TIME(3,30,0)+$J$3/24,"h:mm AM/PM") -> 5:00 AM - 5:30 AM
A8: =TEXT(TIMEVALUE(LEFT(A7,FIND(" -",A7)-1))+TIME(0,30,0),"h:mm AM/PM")&" - "&TEXT(TIMEVALUE(MID(A7,FIND("- ",A7)+2,99))+TIME(0,30,0),"h:mm AM/PM") -> 5:30 AM - 6:00 AM
A9: =TEXT(TIMEVALUE(LEFT(A8,FIND(" -",A8)-1))+TIME(0,30,0),"h:mm AM/PM")&" - "&TEXT(TIMEVALUE(MID(A8,FIND("- ",A8)+2,99))+TIME(0,30,0),"h:mm AM/PM") -> 6:00 AM - 6:30 AM
A10: =TEXT(TIMEVALUE(LEFT(A9,FIND(" -",A9)-1))+TIME(0,30,0),"h:mm AM/PM")&" - "&TEXT(TIMEVALUE(MID(A9,FIND("- ",A9)+2,99))+TIME(0,30,0),"h:mm AM/PM") -> 6:30 AM - 7:00 AM
A11: =TEXT(TIMEVALUE(LEFT(A10,FIND(" -",A10)-1))+TIME(0,30,0),"h:mm AM/PM")&" - "&TEXT(TIMEVALUE(MID(A10,FIND("- ",A10)+2,99))+TIME(0,30,0),"h:mm AM/PM") -> 7:00 AM - 7:30 AM
A12: =TEXT(TIMEVALUE(LEFT(A11,FIND(" -",A11)-1))+TIME(0,30,0),"h:mm AM/PM")&" - "&TEXT(TIMEVALUE(MID(A11,FIND("- ",A11)+2,99))+TIME(0,30,0),"h:mm AM/PM") -> 7:30 AM - 8:00 AM
A13: =TEXT(TIMEVALUE(LEFT(A12,FIND(" -",A12)-1))+TIME(0,30,0),"h:mm AM/PM")&" - "&TEXT(TIMEVALUE(MID(A12,FIND("- ",A12)+2,99))+TIME(0,30,0),"h:mm AM/PM") -> 8:00 AM - 8:30 AM | D13: 1
A14: =TEXT(TIMEVALUE(LEFT(A13,FIND(" -",A13)-1))+TIME(0,30,0),"h:mm AM/PM")&" - "&TEXT(TIMEVALUE(MID(A13,FIND("- ",A13)+2,99))+TIME(0,30,0),"h:mm AM/PM") -> 8:30 AM - 9:00 AM | D14: 1
A15: =TEXT(TIMEVALUE(LEFT(A14,FIND(" -",A14)-1))+TIME(0,30,0),"h:mm AM/PM")&" - "&TEXT(TIMEVALUE(MID(A14,FIND("- ",A14)+2,99))+TIME(0,30,0),"h:mm AM/PM") -> 9:00 AM - 9:30 AM | B15: 1 | C15: 1 | D15: 1 | E15: 1 | F15: 1
A16: =TEXT(TIMEVALUE(LEFT(A15,FIND(" -",A15)-1))+TIME(0,30,0),"h:mm AM/PM")&" - "&TEXT(TIMEVALUE(MID(A15,FIND("- ",A15)+2,99))+TIME(0,30,0),"h:mm AM/PM") -> 9:30 AM - 10:00 AM | B16: 1 | C16: 1 | D16: 1 | E16: 1 | F16: 1
A17: =TEXT(TIMEVALUE(LEFT(A16,FIND(" -",A16)-1))+TIME(0,30,0),"h:mm AM/PM")&" - "&TEXT(TIMEVALUE(MID(A16,FIND("- ",A16)+2,99))+TIME(0,30,0),"h:mm AM/PM") -> 10:00 AM - 10:30 AM | B17: 1 | C17: 1 | D17: 1 | E17: 1 | F17: 1
A18: =TEXT(TIMEVALUE(LEFT(A17,FIND(" -",A17)-1))+TIME(0,30,0),"h:mm AM/PM")&" - "&TEXT(TIMEVALUE(MID(A17,FIND("- ",A17)+2,99))+TIME(0,30,0),"h:mm AM/PM") -> 10:30 AM - 11:00 AM | B18: 1 | C18: 1 | D18: 1 | E18: 1
A19: =TEXT(TIMEVALUE(LEFT(A18,FIND(" -",A18)-1))+TIME(0,30,0),"h:mm AM/PM")&" - "&TEXT(TIMEVALUE(MID(A18,FIND("- ",A18)+2,99))+TIME(0,30,0),"h:mm AM/PM") -> 11:00 AM - 11:30 AM | B19: 1 | C19: 1 | D19: 1 | E19: 1
A20: =TEXT(TIMEVALUE(LEFT(A19,FIND(" -",A19)-1))+TIME(0,30,0),"h:mm AM/PM")&" - "&TEXT(TIMEVALUE(MID(A19,FIND("- ",A19)+2,99))+TIME(0,30,0),"h:mm AM/PM") -> 11:30 AM - 12:00 PM | B20: 1 | C20: 1 | D20: 1 | E20: 1
A21: =TEXT(TIMEVALUE(LEFT(A20,FIND(" -",A20)-1))+TIME(0,30,0),"h:mm AM/PM")&" - "&TEXT(TIMEVALUE(MID(A20,FIND("- ",A20)+2,99))+TIME(0,30,0),"h:mm AM/PM") -> 12:00 PM - 12:30 PM | C21: 1 | E21: 1
A22: =TEXT(TIMEVALUE(LEFT(A21,FIND(" -",A21)-1))+TIME(0,30,0),"h:mm AM/PM")&" - "&TEXT(TIMEVALUE(MID(A21,FIND("- ",A21)+2,99))+TIME(0,30,0),"h:mm AM/PM") -> 12:30 PM - 1:00 PM | C22: 1 | E22: 1
A23: =TEXT(TIMEVALUE(LEFT(A22,FIND(" -",A22)-1))+TIME(0,30,0),"h:mm AM/PM")&" - "&TEXT(TIMEVALUE(MID(A22,FIND("- ",A22)+2,99))+TIME(0,30,0),"h:mm AM/PM") -> 1:00 PM - 1:30 PM | C23: 1 | E23: 1
A24: =TEXT(TIMEVALUE(LEFT(A23,FIND(" -",A23)-1))+TIME(0,30,0),"h:mm AM/PM")&" - "&TEXT(TIMEVALUE(MID(A23,FIND("- ",A23)+2,99))+TIME(0,30,0),"h:mm AM/PM") -> 1:30 PM - 2:00 PM | C24: 1 | E24: 1
A25: =TEXT(TIMEVALUE(LEFT(A24,FIND(" -",A24)-1))+TIME(0,30,0),"h:mm AM/PM")&" - "&TEXT(TIMEVALUE(MID(A24,FIND("- ",A24)+2,99))+TIME(0,30,0),"h:mm AM/PM") -> 2:00 PM - 2:30 PM | B25: 1 | C25: 1 | D25: 1 | E25: 1
A26: =TEXT(TIMEVALUE(LEFT(A25,FIND(" -",A25)-1))+TIME(0,30,0),"h:mm AM/PM")&" - "&TEXT(TIMEVALUE(MID(A25,FIND("- ",A25)+2,99))+TIME(0,30,0),"h:mm AM/PM") -> 2:30 PM - 3:00 PM | B26: 1 | C26: 1 | D26: 1 | E26: 1
A27: =TEXT(TIMEVALUE(LEFT(A26,FIND(" -",A26)-1))+TIME(0,30,0),"h:mm AM/PM")&" - "&TEXT(TIMEVALUE(MID(A26,FIND("- ",A26)+2,99))+TIME(0,30,0),"h:mm AM/PM") -> 3:00 PM - 3:30 PM | B27: 1 | C27: 1 | D27: 1 | E27: 1
A28: =TEXT(TIMEVALUE(LEFT(A27,FIND(" -",A27)-1))+TIME(0,30,0),"h:mm AM/PM")&" - "&TEXT(TIMEVALUE(MID(A27,FIND("- ",A27)+2,99))+TIME(0,30,0),"h:mm AM/PM") -> 3:30 PM - 4:00 PM | B28: 1 | C28: 1 | D28: 1 | E28: 1
A29: =TEXT(TIMEVALUE(LEFT(A28,FIND(" -",A28)-1))+TIME(0,30,0),"h:mm AM/PM")&" - "&TEXT(TIMEVALUE(MID(A28,FIND("- ",A28)+2,99))+TIME(0,30,0),"h:mm AM/PM") -> 4:00 PM - 4:30 PM | D29: 1 | F29: 1
A30: =TEXT(TIMEVALUE(LEFT(A29,FIND(" -",A29)-1))+TIME(0,30,0),"h:mm AM/PM")&" - "&TEXT(TIMEVALUE(MID(A29,FIND("- ",A29)+2,99))+TIME(0,30,0),"h:mm AM/PM") -> 4:30 PM - 5:00 PM | F30: 1
A31: =TEXT(TIMEVALUE(LEFT(A30,FIND(" -",A30)-1))+TIME(0,30,0),"h:mm AM/PM")&" - "&TEXT(TIMEVALUE(MID(A30,FIND("- ",A30)+2,99))+TIME(0,30,0),"h:mm AM/PM") -> 5:00 PM - 5:30 PM
A32: =TEXT(TIMEVALUE(LEFT(A31,FIND(" -",A31)-1))+TIME(0,30,0),"h:mm AM/PM")&" - "&TEXT(TIMEVALUE(MID(A31,FIND("- ",A31)+2,99))+TIME(0,30,0),"h:mm AM/PM") -> 5:30 PM - 6:00 PM
A33: =TEXT(TIMEVALUE(LEFT(A32,FIND(" -",A32)-1))+TIME(0,30,0),"h:mm AM/PM")&" - "&TEXT(TIMEVALUE(MID(A32,FIND("- ",A32)+2,99))+TIME(0,30,0),"h:mm AM/PM") -> 6:00 PM - 6:30 PM | E33: 1
A34: =TEXT(TIMEVALUE(LEFT(A33,FIND(" -",A33)-1))+TIME(0,30,0),"h:mm AM/PM")&" - "&TEXT(TIMEVALUE(MID(A33,FIND("- ",A33)+2,99))+TIME(0,30,0),"h:mm AM/PM") -> 6:30 PM - 7:00 PM | E34: 1
A35: =TEXT(TIMEVALUE(LEFT(A34,FIND(" -",A34)-1))+TIME(0,30,0),"h:mm AM/PM")&" - "&TEXT(TIMEVALUE(MID(A34,FIND("- ",A34)+2,99))+TIME(0,30,0),"h:mm AM/PM") -> 7:00 PM - 7:30 PM
A36: =TEXT(TIMEVALUE(LEFT(A35,FIND(" -",A35)-1))+TIME(0,30,0),"h:mm AM/PM")&" - "&TEXT(TIMEVALUE(MID(A35,FIND("- ",A35)+2,99))+TIME(0,30,0),"h:mm AM/PM") -> 7:30 PM - 8:00 PM
A37: =TEXT(TIMEVALUE(LEFT(A36,FIND(" -",A36)-1))+TIME(0,30,0),"h:mm AM/PM")&" - "&TEXT(TIMEVALUE(MID(A36,FIND("- ",A36)+2,99))+TIME(0,30,0),"h:mm AM/PM") -> 8:00 PM - 8:30 PM
A38: =TEXT(TIMEVALUE(LEFT(A37,FIND(" -",A37)-1))+TIME(0,30,0),"h:mm AM/PM")&" - "&TEXT(TIMEVALUE(MID(A37,FIND("- ",A37)+2,99))+TIME(0,30,0),"h:mm AM/PM") -> 8:30 PM - 9:00 PM
A39: =TEXT(TIMEVALUE(LEFT(A38,FIND(" -",A38)-1))+TIME(0,30,0),"h:mm AM/PM")&" - "&TEXT(TIMEVALUE(MID(A38,FIND("- ",A38)+2,99))+TIME(0,30,0),"h:mm AM/PM") -> 9:00 PM - 9:30 PM
A40: =TEXT(TIMEVALUE(LEFT(A39,FIND(" -",A39)-1))+TIME(0,30,0),"h:mm AM/PM")&" - "&TEXT(TIMEVALUE(MID(A39,FIND("- ",A39)+2,99))+TIME(0,30,0),"h:mm AM/PM") -> 9:30 PM - 10:00 PM
A41: =TEXT(TIMEVALUE(LEFT(A40,FIND(" -",A40)-1))+TIME(0,30,0),"h:mm AM/PM")&" - "&TEXT(TIMEVALUE(MID(A40,FIND("- ",A40)+2,99))+TIME(0,30,0),"h:mm AM/PM") -> 10:00 PM - 10:30 PM
A42: =TEXT(TIMEVALUE(LEFT(A41,FIND(" -",A41)-1))+TIME(0,30,0),"h:mm AM/PM")&" - "&TEXT(TIMEVALUE(MID(A41,FIND("- ",A41)+2,99))+TIME(0,30,0),"h:mm AM/PM") -> 10:30 PM - 11:00 PM
...

Sheet Colin Hui
A1: Step 1: Rename the sheet name with your name, for example 'Member 2 Name' to 'Your Name' | J1: Time Zone
A2: Step 2: Choose your time zone from yellow drop down box | J2: EST
A3: Step 3: Enter '1' in all 30-minute slots you're NOT available in orange area | J3: {=_xlfn.SWITCH(J2,"PST",0,"MST",1,"CST",2,"EST",3,0)} -> 3
A6: Time | B6: Monday | C6: Tuesday | D6: Wednesday | E6: Thursday | F6: Friday | G6: Saturday | H6: Sunday
A7: =TEXT(TIME(3,0,0)+$J$3/24,"h:mm AM/PM")&" - "&TEXT(TIME(3,30,0)+$J$3/24,"h:mm AM/PM") -> 6:00 AM - 6:30 AM | B7: 1 | C7: 1 | D7: 1 | E7: 1 | F7: 1 | G7: 1 | H7: 1
A8: =TEXT(TIMEVALUE(LEFT(A7,FIND(" -",A7)-1))+TIME(0,30,0),"h:mm AM/PM")&" - "&TEXT(TIMEVALUE(MID(A7,FIND("- ",A7)+2,99))+TIME(0,30,0),"h:mm AM/PM") -> 6:30 AM - 7:00 AM | B8: 1 | C8: 1 | D8: 1 | E8: 1 | F8: 1 | G8: 1 | H8: 1
A9: =TEXT(TIMEVALUE(LEFT(A8,FIND(" -",A8)-1))+TIME(0,30,0),"h:mm AM/PM")&" - "&TEXT(TIMEVALUE(MID(A8,FIND("- ",A8)+2,99))+TIME(0,30,0),"h:mm AM/PM") -> 7:00 AM - 7:30 AM | B9: 1 | C9: 1 | D9: 1 | E9: 1 | F9: 1 | G9: 1 | H9: 1
A10: =TEXT(TIMEVALUE(LEFT(A9,FIND(" -",A9)-1))+TIME(0,30,0),"h:mm AM/PM")&" - "&TEXT(TIMEVALUE(MID(A9,FIND("- ",A9)+2,99))+TIME(0,30,0),"h:mm AM/PM") -> 7:30 AM - 8:00 AM | B10: 1 | C10: 1 | D10: 1 | E10: 1 | F10: 1 | G10: 1 | H10: 1
A11: =TEXT(TIMEVALUE(LEFT(A10,FIND(" -",A10)-1))+TIME(0,30,0),"h:mm AM/PM")&" - "&TEXT(TIMEVALUE(MID(A10,FIND("- ",A10)+2,99))+TIME(0,30,0),"h:mm AM/PM") -> 8:00 AM - 8:30 AM | B11: 1 | C11: 1 | D11: 1 | E11: 1 | F11: 1 | G11: 1 | H11: 1
A12: =TEXT(TIMEVALUE(LEFT(A11,FIND(" -",A11)-1))+TIME(0,30,0),"h:mm AM/PM")&" - "&TEXT(TIMEVALUE(MID(A11,FIND("- ",A11)+2,99))+TIME(0,30,0),"h:mm AM/PM") -> 8:30 AM - 9:00 AM | B12: 1 | C12: 1 | D12: 1 | E12: 1 | F12: 1 | G12: 1 | H12: 1
A13: =TEXT(TIMEVALUE(LEFT(A12,FIND(" -",A12)-1))+TIME(0,30,0),"h:mm AM/PM")&" - "&TEXT(TIMEVALUE(MID(A12,FIND("- ",A12)+2,99))+TIME(0,30,0),"h:mm AM/PM") -> 9:00 AM - 9:30 AM | B13: 1 | C13: 1 | D13: 1 | E13: 1 | F13: 1
A14: =TEXT(TIMEVALUE(LEFT(A13,FIND(" -",A13)-1))+TIME(0,30,0),"h:mm AM/PM")&" - "&TEXT(TIMEVALUE(MID(A13,FIND("- ",A13)+2,99))+TIME(0,30,0),"h:mm AM/PM") -> 9:30 AM - 10:00 AM | B14: 1 | C14: 1 | D14: 1 | E14: 1 | F14: 1
A15: =TEXT(TIMEVALUE(LEFT(A14,FIND(" -",A14)-1))+TIME(0,30,0),"h:mm AM/PM")&" - "&TEXT(TIMEVALUE(MID(A14,FIND("- ",A14)+2,99))+TIME(0,30,0),"h:mm AM/PM") -> 10:00 AM - 10:30 AM | B15: 1 | C15: 1 | D15: 1 | E15: 1 | F15: 1
A16: =TEXT(TIMEVALUE(LEFT(A15,FIND(" -",A15)-1))+TIME(0,30,0),"h:mm AM/PM")&" - "&TEXT(TIMEVALUE(MID(A15,FIND("- ",A15)+2,99))+TIME(0,30,0),"h:mm AM/PM") -> 10:30 AM - 11:00 AM | B16: 1 | C16: 1 | D16: 1 | E16: 1 | F16: 1
A17: =TEXT(TIMEVALUE(LEFT(A16,FIND(" -",A16)-1))+TIME(0,30,0),"h:mm AM/PM")&" - "&TEXT(TIMEVALUE(MID(A16,FIND("- ",A16)+2,99))+TIME(0,30,0),"h:mm AM/PM") -> 11:00 AM - 11:30 AM | B17: 1 | C17: 1 | D17: 1 | E17: 1 | F17: 1
A18: =TEXT(TIMEVALUE(LEFT(A17,FIND(" -",A17)-1))+TIME(0,30,0),"h:mm AM/PM")&" - "&TEXT(TIMEVALUE(MID(A17,FIND("- ",A17)+2,99))+TIME(0,30,0),"h:mm AM/PM") -> 11:30 AM - 12:00 PM
A19: =TEXT(TIMEVALUE(LEFT(A18,FIND(" -",A18)-1))+TIME(0,30,0),"h:mm AM/PM")&" - "&TEXT(TIMEVALUE(MID(A18,FIND("- ",A18)+2,99))+TIME(0,30,0),"h:mm AM/PM") -> 12:00 PM - 12:30 PM
A20: =TEXT(TIMEVALUE(LEFT(A19,FIND(" -",A19)-1))+TIME(0,30,0),"h:mm AM/PM")&" - "&TEXT(TIMEVALUE(MID(A19,FIND("- ",A19)+2,99))+TIME(0,30,0),"h:mm AM/PM") -> 12:30 PM - 1:00 PM
A21: =TEXT(TIMEVALUE(LEFT(A20,FIND(" -",A20)-1))+TIME(0,30,0),"h:mm AM/PM")&" - "&TEXT(TIMEVALUE(MID(A20,FIND("- ",A20)+2,99))+TIME(0,30,0),"h:mm AM/PM") -> 1:00 PM - 1:30 PM
A22: =TEXT(TIMEVALUE(LEFT(A21,FIND(" -",A21)-1))+TIME(0,30,0),"h:mm AM/PM")&" - "&TEXT(TIMEVALUE(MID(A21,FIND("- ",A21)+2,99))+TIME(0,30,0),"h:mm AM/PM") -> 1:30 PM - 2:00 PM
A23: =TEXT(TIMEVALUE(LEFT(A22,FIND(" -",A22)-1))+TIME(0,30,0),"h:mm AM/PM")&" - "&TEXT(TIMEVALUE(MID(A22,FIND("- ",A22)+2,99))+TIME(0,30,0),"h:mm AM/PM") -> 2:00 PM - 2:30 PM
A24: =TEXT(TIMEVALUE(LEFT(A23,FIND(" -",A23)-1))+TIME(0,30,0),"h:mm AM/PM")&" - "&TEXT(TIMEVALUE(MID(A23,FIND("- ",A23)+2,99))+TIME(0,30,0),"h:mm AM/PM") -> 2:30 PM - 3:00 PM
A25: =TEXT(TIMEVALUE(LEFT(A24,FIND(" -",A24)-1))+TIME(0,30,0),"h:mm AM/PM")&" - "&TEXT(TIMEVALUE(MID(A24,FIND("- ",A24)+2,99))+TIME(0,30,0),"h:mm AM/PM") -> 3:00 PM - 3:30 PM
A26: =TEXT(TIMEVALUE(LEFT(A25,FIND(" -",A25)-1))+TIME(0,30,0),"h:mm AM/PM")&" - "&TEXT(TIMEVALUE(MID(A25,FIND("- ",A25)+2,99))+TIME(0,30,0),"h:mm AM/PM") -> 3:30 PM - 4:00 PM
A27: =TEXT(TIMEVALUE(LEFT(A26,FIND(" -",A26)-1))+TIME(0,30,0),"h:mm AM/PM")&" - "&TEXT(TIMEVALUE(MID(A26,FIND("- ",A26)+2,99))+TIME(0,30,0),"h:mm AM/PM") -> 4:00 PM - 4:30 PM
A28: =TEXT(TIMEVALUE(LEFT(A27,FIND(" -",A27)-1))+TIME(0,30,0),"h:mm AM/PM")&" - "&TEXT(TIMEVALUE(MID(A27,FIND("- ",A27)+2,99))+TIME(0,30,0),"h:mm AM/PM") -> 4:30 PM - 5:00 PM
A29: =TEXT(TIMEVALUE(LEFT(A28,FIND(" -",A28)-1))+TIME(0,30,0),"h:mm AM/PM")&" - "&TEXT(TIMEVALUE(MID(A28,FIND("- ",A28)+2,99))+TIME(0,30,0),"h:mm AM/PM") -> 5:00 PM - 5:30 PM
... A32: =TEXT(TIMEVALUE(LEFT(A31,FIND(" -",A31)-1))+TIME(0,30,0),"h:mm AM/PM")&" - "&TEXT(TIMEVALUE(MID(A31,FIND("- ",A31)+2,99))+TIME(0,30,0),"h:mm AM/PM") -> 6:30 PM - 7:00 PM
A33: =TEXT(TIMEVALUE(LEFT(A32,FIND(" -",A32)-1))+TIME(0,30,0),"h:mm AM/PM")&" - "&TEXT(TIMEVALUE(MID(A32,FIND("- ",A32)+2,99))+TIME(0,30,0),"h:mm AM/PM") -> 7:00 PM - 7:30 PM | B33: 1 | D33: 1 | E33: 1
A34: =TEXT(TIMEVALUE(LEFT(A33,FIND(" -",A33)-1))+TIME(0,30,0),"h:mm AM/PM")&" - "&TEXT(TIMEVALUE(MID(A33,FIND("- ",A33)+2,99))+TIME(0,30,0),"h:mm AM/PM") -> 7:30 PM - 8:00 PM | B34: 1 | D34: 1 | E34: 1
A35: =TEXT(TIMEVALUE(LEFT(A34,FIND(" -",A34)-1))+TIME(0,30,0),"h:mm AM/PM")&" - "&TEXT(TIMEVALUE(MID(A34,FIND("- ",A34)+2,99))+TIME(0,30,0),"h:mm AM/PM") -> 8:00 PM - 8:30 PM | B35: 1 | D35: 1 | E35: 1
A36: =TEXT(TIMEVALUE(LEFT(A35,FIND(" -",A35)-1))+TIME(0,30,0),"h:mm AM/PM")&" - "&TEXT(TIMEVALUE(MID(A35,FIND("- ",A35)+2,99))+TIME(0,30,0),"h:mm AM/PM") -> 8:30 PM - 9:00 PM | B36: 1 | D36: 1 | E36: 1
A37: =TEXT(TIMEVALUE(LEFT(A36,FIND(" -",A36)-1))+TIME(0,30,0),"h:mm AM/PM")&" - "&TEXT(TIMEVALUE(MID(A36,FIND("- ",A36)+2,99))+TIME(0,30,0),"h:mm AM/PM") -> 9:00 PM - 9:30 PM | B37: 1 | D37: 1 | E37: 1
A38: =TEXT(TIMEVALUE(LEFT(A37,FIND(" -",A37)-1))+TIME(0,30,0),"h:mm AM/PM")&" - "&TEXT(TIMEVALUE(MID(A37,FIND("- ",A37)+2,99))+TIME(0,30,0),"h:mm AM/PM") -> 9:30 PM - 10:00 PM | B38: 1 | D38: 1 | E38: 1
A39: =TEXT(TIMEVALUE(LEFT(A38,FIND(" -",A38)-1))+TIME(0,30,0),"h:mm AM/PM")&" - "&TEXT(TIMEVALUE(MID(A38,FIND("- ",A38)+2,99))+TIME(0,30,0),"h:mm AM/PM") -> 10:00 PM - 10:30 PM | B39: 1 | D39: 1 | E39: 1
A40: =TEXT(TIMEVALUE(LEFT(A39,FIND(" -",A39)-1))+TIME(0,30,0),"h:mm AM/PM")&" - "&TEXT(TIMEVALUE(MID(A39,FIND("- ",A39)+2,99))+TIME(0,30,0),"h:mm AM/PM") -> 10:30 PM - 11:00 PM | B40: 1 | D40: 1 | E40: 1
A41: =TEXT(TIMEVALUE(LEFT(A40,FIND(" -",A40)-1))+TIME(0,30,0),"h:mm AM/PM")&" - "&TEXT(TIMEVALUE(MID(A40,FIND("- ",A40)+2,99))+TIME(0,30,0),"h:mm AM/PM") -> 11:00 PM - 11:30 PM
A42: =TEXT(TIMEVALUE(LEFT(A41,FIND(" -",A41)-1))+TIME(0,30,0),"h:mm AM/PM")&" - "&TEXT(TIMEVALUE(MID(A41,FIND("- ",A41)+2,99))+TIME(0,30,0),"h:mm AM/PM") -> 11:30 PM - 12:00 AM
A43: =TEXT(TIMEVALUE(LEFT(A42,FIND(" -",A42)-1))+TIME(0,30,0),"h:mm AM/PM")&" - "&TEXT(TIMEVALUE(MID(A42,FIND("- ",A42)+2,99))+TIME(0,30,0),"h:mm AM/PM") -> 12:00 AM - 12:30 AM

Sheet Iris Liu
A1: Step 1: Rename the sheet name with your name, for example 'Member 3 Name' to 'Your Name' | J1: Time Zone
A2: Step 2: Choose your time zone from yellow drop down box | J2: PST
A3: Step 3: Enter '1' in all 30-minute slots you're NOT available in orange area | J3: {=_xlfn.SWITCH(J2,"PST",0,"MST",1,"CST",2,"EST",3,0)} -> 0
A6: Time | B6: Monday | C6: Tuesday | D6: Wednesday | E6: Thursday | F6: Friday | G6: Saturday | H6: Sunday
A7: =TEXT(TIME(3,0,0)+$J$3/24,"h:mm AM/PM")&" - "&TEXT(TIME(3,30,0)+$J$3/24,"h:mm AM/PM") -> 3:00 AM - 3:30 AM | B7: 1 | C7: 1 | D7: 1 | E7: 1 | F7: 1 | G7: 1 | H7: 1
A8: =TEXT(TIMEVALUE(LEFT(A7,FIND(" -",A7)-1))+TIME(0,30,0),"h:mm AM/PM")&" - "&TEXT(TIMEVALUE(MID(A7,FIND("- ",A7)+2,99))+TIME(0,30,0),"h:mm AM/PM") -> 3:30 AM - 4:00 AM | B8: 1 | C8: 1 | D8: 1 | E8: 1 | F8: 1 | G8: 1 | H8: 1
A9: =TEXT(TIMEVALUE(LEFT(A8,FIND(" -",A8)-1))+TIME(0,30,0),"h:mm AM/PM")&" - "&TEXT(TIMEVALUE(MID(A8,FIND("- ",A8)+2,99))+TIME(0,30,0),"h:mm AM/PM") -> 4:00 AM - 4:30 AM | B9: 1 | C9: 1 | D9: 1 | E9: 1 | F9: 1 | G9: 1 | H9: 1
A10: =TEXT(TIMEVALUE(LEFT(A9,FIND(" -",A9)-1))+TIME(0,30,0),"h:mm AM/PM")&" - "&TEXT(TIMEVALUE(MID(A9,FIND("- ",A9)+2,99))+TIME(0,30,0),"h:mm AM/PM") -> 4:30 AM - 5:00 AM | B10: 1 | C10: 1 | D10: 1 | E10: 1 | F10: 1 | G10: 1 | H10: 1
A11: =TEXT(TIMEVALUE(LEFT(A10,FIND(" -",A10)-1))+TIME(0,30,0),"h:mm AM/PM")&" - "&TEXT(TIMEVALUE(MID(A10,FIND("- ",A10)+2,99))+TIME(0,30,0),"h:mm AM/PM") -> 5:00 AM - 5:30 AM | B11: 1 | C11: 1 | D11: 1 | E11: 1 | F11: 1 | G11: 1 | H11: 1
A12: =TEXT(TIMEVALUE(LEFT(A11,FIND(" -",A11)-1))+TIME(0,30,0),"h:mm AM/PM")&" - "&TEXT(TIMEVALUE(MID(A11,FIND("- ",A11)+2,99))+TIME(0,30,0),"h:mm AM/PM") -> 5:30 AM - 6:00 AM | B12: 1 | C12: 1 | D12: 1 | E12: 1 | F12: 1 | G12: 1 | H12: 1
A13: =TEXT(TIMEVALUE(LEFT(A12,FIND(" -",A12)-1))+TIME(0,30,0),"h:mm AM/PM")&" - "&TEXT(TIMEVALUE(MID(A12,FIND("- ",A12)+2,99))+TIME(0,30,0),"h:mm AM/PM") -> 6:00 AM - 6:30 AM | B13: 1 | C13: 1 | D13: 1 | E13: 1 | F13: 1 | G13: 1 | H13: 1
A14: =TEXT(TIMEVALUE(LEFT(A13,FIND(" -",A13)-1))+TIME(0,30,0),"h:mm AM/PM")&" - "&TEXT(TIMEVALUE(MID(A13,FIND("- ",A13)+2,99))+TIME(0,30,0),"h:mm AM/PM") -> 6:30 AM - 7:00 AM | B14: 1 | C14: 1 | D14: 1 | E14: 1 | F14: 1 | G14: 1 | H14: 1
A15: =TEXT(TIMEVALUE(LEFT(A14,FIND(" -",A14)-1))+TIME(0,30,0),"h:mm AM/PM")&" - "&TEXT(TIMEVALUE(MID(A14,FIND("- ",A14)+2,99))+TIME(0,30,0),"h:mm AM/PM") -> 7:00 AM - 7:30 AM | B15: 1 | C15: 1 | D15: 1 | E15: 1 | F15: 1 | G15: 1 | H15: 1
A16: =TEXT(TIMEVALUE(LEFT(A15,FIND(" -",A15)-1))+TIME(0,30,0),"h:mm AM/PM")&" - "&TEXT(TIMEVALUE(MID(A15,FIND("- ",A15)+2,99))+TIME(0,30,0),"h:mm AM/PM") -> 7:30 AM - 8:00 AM | B16: 1 | C16: 1 | D16: 1 | E16: 1 | F16: 1 | G16: 1 | H16: 1
A17: =TEXT(TIMEVALUE(LEFT(A16,FIND(" -",A16)-1))+TIME(0,30,0),"h:mm AM/PM")&" - "&TEXT(TIMEVALUE(MID(A16,FIND("- ",A16)+2,99))+TIME(0,30,0),"h:mm AM/PM") -> 8:00 AM - 8:30 AM | B17: 1 | C17: 1 | D17: 1 | E17: 1 | F17: 1 | G17: 1 | H17: 1
A18: =TEXT(TIMEVALUE(LEFT(A17,FIND(" -",A17)-1))+TIME(0,30,0),"h:mm AM/PM")&" - "&TEXT(TIMEVALUE(MID(A17,FIND("- ",A17)+2,99))+TIME(0,30,0),"h:mm AM/PM") -> 8:30 AM - 9:00 AM | B18: 1 | C18: 1 | D18: 1 | E18: 1 | F18: 1 | G18: 1 | H18: 1
A19: =TEXT(TIMEVALUE(LEFT(A18,FIND(" -",A18)-1))+TIME(0,30,0),"h:mm AM/PM")&" - "&TEXT(TIMEVALUE(MID(A18,FIND("- ",A18)+2,99))+TIME(0,30,0),"h:mm AM/PM") -> 9:00 AM - 9:30 AM | C19: 1 | E19: 1 | F19: 1 | G19: 1 | H19: 1
A20: =TEXT(TIMEVALUE(LEFT(A19,FIND(" -",A19)-1))+TIME(0,30,0),"h:mm AM/PM")&" - "&TEXT(TIMEVALUE(MID(A19,FIND("- ",A19)+2,99))+TIME(0,30,0),"h:mm AM/PM") -> 9:30 AM - 10:00 AM | C20: 1 | E20: 1 | G20: 1 | H20: 1
A21: =TEXT(TIMEVALUE(LEFT(A20,FIND(" -",A20)-1))+TIME(0,30,0),"h:mm AM/PM")&" - "&TEXT(TIMEVALUE(MID(A20,FIND("- ",A20)+2,99))+TIME(0,30,0),"h:mm AM/PM") -> 10:00 AM - 10:30 AM | C21: 1 | E21: 1
A22: =TEXT(TIMEVALUE(LEFT(A21,FIND(" -",A21)-1))+TIME(0,30,0),"h:mm AM/PM")&" - "&TEXT(TIMEVALUE(MID(A21,FIND("- ",A21)+2,99))+TIME(0,30,0),"h:mm AM/PM") -> 10:30 AM - 11:00 AM
A23: =TEXT(TIMEVALUE(LEFT(A22,FIND(" -",A22)-1))+TIME(0,30,0),"h:mm AM/PM")&" - "&TEXT(TIMEVALUE(MID(A22,FIND("- ",A22)+2,99))+TIME(0,30,0),"h:mm AM/PM") -> 11:00 AM - 11:30 AM
A24: =TEXT(TIMEVALUE(LEFT(A23,FIND(" -",A23)-1))+TIME(0,30,0),"h:mm AM/PM")&" - "&TEXT(TIMEVALUE(MID(A23,FIND("- ",A23)+2,99))+TIME(0,30,0),"h:mm AM/PM") -> 11:30 AM - 12:00 PM | C24: 1 | E24: 1
A25: =TEXT(TIMEVALUE(LEFT(A24,FIND(" -",A24)-1))+TIME(0,30,0),"h:mm AM/PM")&" - "&TEXT(TIMEVALUE(MID(A24,FIND("- ",A24)+2,99))+TIME(0,30,0),"h:mm AM/PM") -> 12:00 PM - 12:30 PM | C25: 1 | E25: 1
A26: =TEXT(TIMEVALUE(LEFT(A25,FIND(" -",A25)-1))+TIME(0,30,0),"h:mm AM/PM")&" - "&TEXT(TIMEVALUE(MID(A25,FIND("- ",A25)+2,99))+TIME(0,30,0),"h:mm AM/PM") -> 12:30 PM - 1:00 PM | C26: 1 | D26: 1 | E26: 1
A27: =TEXT(TIMEVALUE(LEFT(A26,FIND(" -",A26)-1))+TIME(0,30,0),"h:mm AM/PM")&" - "&TEXT(TIMEVALUE(MID(A26,FIND("- ",A26)+2,99))+TIME(0,30,0),"h:mm AM/PM") -> 1:00 PM - 1:30 PM | C27: 1 | D27: 1 | E27: 1
A28: =TEXT(TIMEVALUE(LEFT(A27,FIND(" -",A27)-1))+TIME(0,30,0),"h:mm AM/PM")&" - "&TEXT(TIMEVALUE(MID(A27,FIND("- ",A27)+2,99))+TIME(0,30,0),"h:mm AM/PM") -> 1:30 PM - 2:00 PM | C28: 1 | D28: 1 | E28: 1
A29: =TEXT(TIMEVALUE(LEFT(A28,FIND(" -",A28)-1))+TIME(0,30,0),"h:mm AM/PM")&" - "&TEXT(TIMEVALUE(MID(A28,FIND("- ",A28)+2,99))+TIME(0,30,0),"h:mm AM/PM") -> 2:00 PM - 2:30 PM | C29: 1
A30: =TEXT(TIMEVALUE(LEFT(A29,FIND(" -",A29)-1))+TIME(0,30,0),"h:mm AM/PM")&" - "&TEXT(TIMEVALUE(MID(A29,FIND("- ",A29)+2,99))+TIME(0,30,0),"h:mm AM/PM") -> 2:30 PM - 3:00 PM | C30: 1
A31: =TEXT(TIMEVALUE(LEFT(A30,FIND(" -",A30)-1))+TIME(0,30,0),"h:mm AM/PM")&" - "&TEXT(TIMEVALUE(MID(A30,FIND("- ",A30)+2,99))+TIME(0,30,0),"h:mm AM/PM") -> 3:00 PM - 3:30 PM | B31: 1 | C31: 1 | D31: 1
A32: =TEXT(TIMEVALUE(LEFT(A31,FIND(" -",A31)-1))+TIME(0,30,0),"h:mm AM/PM")&" - "&TEXT(TIMEVALUE(MID(A31,FIND("- ",A31)+2,99))+TIME(0,30,0),"h:mm AM/PM") -> 3:30 PM - 4:00 PM | B32: 1 | C32: 1 | D32: 1
A33: =TEXT(TIMEVALUE(LEFT(A32,FIND(" -",A32)-1))+TIME(0,30,0),"h:mm AM/PM")&" - "&TEXT(TIMEVALUE(MID(A32,FIND("- ",A32)+2,99))+TIME(0,30,0),"h:mm AM/PM") -> 4:00 PM - 4:30 PM | B33: 1 | C33: 1 | D33: 1
A34: =TEXT(TIMEVALUE(LEFT(A33,FIND(" -",A33)-1))+TIME(0,30,0),"h:mm AM/PM")&" - "&TEXT(TIMEVALUE(MID(A33,FIND("- ",A33)+2,99))+TIME(0,30,0),"h:mm AM/PM") -> 4:30 PM - 5:00 PM | B34: 1 | C34: 1 | D34: 1
A35: =TEXT(TIMEVALUE(LEFT(A34,FIND(" -",A34)-1))+TIME(0,30,0),"h:mm AM/PM")&" - "&TEXT(TIMEVALUE(MID(A34,FIND("- ",A34)+2,99))+TIME(0,30,0),"h:mm AM/PM") -> 5:00 PM - 5:30 PM | C35: 1
A36: =TEXT(TIMEVALUE(LEFT(A35,FIND(" -",A35)-1))+TIME(0,30,0),"h:mm AM/PM")&" - "&TEXT(TIMEVALUE(MID(A35,FIND("- ",A35)+2,99))+TIME(0,30,0),"h:mm AM/PM") -> 5:30 PM - 6:00 PM
A37: =TEXT(TIMEVALUE(LEFT(A36,FIND(" -",A36)-1))+TIME(0,30,0),"h:mm AM/PM")&" - "&TEXT(TIMEVALUE(MID(A36,FIND("- ",A36)+2,99))+TIME(0,30,0),"h:mm AM/PM") -> 6:00 PM - 6:30 PM
A38: =TEXT(TIMEVALUE(LEFT(A37,FIND(" -",A37)-1))+TIME(0,30,0),"h:mm AM/PM")&" - "&TEXT(TIMEVALUE(MID(A37,FIND("- ",A37)+2,99))+TIME(0,30,0),"h:mm AM/PM") -> 6:30 PM - 7:00 PM
A39: =TEXT(TIMEVALUE(LEFT(A38,FIND(" -",A38)-1))+TIME(0,30,0),"h:mm AM/PM")&" - "&TEXT(TIMEVALUE(MID(A38,FIND("- ",A38)+2,99))+TIME(0,30,0),"h:mm AM/PM") -> 7:00 PM - 7:30 PM
A40: =TEXT(TIMEVALUE(LEFT(A39,FIND(" -",A39)-1))+TIME(0,30,0),"h:mm AM/PM")&" - "&TEXT(TIMEVALUE(MID(A39,FIND("- ",A39)+2,99))+TIME(0,30,0),"h:mm AM/PM") -> 7:30 PM - 8:00 PM
A41: =TEXT(TIMEVALUE(LEFT(A40,FIND(" -",A40)-1))+TIME(0,30,0),"h:mm AM/PM")&" - "&TEXT(TIMEVALUE(MID(A40,FIND("- ",A40)+2,99))+TIME(0,30,0),"h:mm AM/PM") -> 8:00 PM - 8:30 PM
A42: =TEXT(TIMEVALUE(LEFT(A41,FIND(" -",A41)-1))+TIME(0,30,0),"h:mm AM/PM")&" - "&TEXT(TIMEVALUE(MID(A41,FIND("- ",A41)+2,99))+TIME(0,30,0),"h:mm AM/PM") -> 8:30 PM - 9:00 PM
...

Sheet Max McCarter
A1: Step 1: Rename the sheet name with your name, for example 'Member 4 Name' to 'Your Name' | J1: Time Zone
A2: Step 2: Choose your time zone from yellow drop down box | J2: CST
A3: Step 3: Enter '1' in all 30-minute slots you're NOT available in orange area | J3: {=_xlfn.SWITCH(J2,"PST",0,"MST",1,"CST",2,"EST",3,0)} -> 2
A6: Time | B6: Monday | C6: Tuesday | D6: Wednesday | E6: Thursday | F6: Friday | G6: Saturday | H6: Sunday
A7: =TEXT(TIME(3,0,0)+$J$3/24,"h:mm AM/PM")&" - "&TEXT(TIME(3,30,0)+$J$3/24,"h:mm AM/PM") -> 5:00 AM - 5:30 AM
A8: =TEXT(TIMEVALUE(LEFT(A7,FIND(" -",A7)-1))+TIME(0,30,0),"h:mm AM/PM")&" - "&TEXT(TIMEVALUE(MID(A7,FIND("- ",A7)+2,99))+TIME(0,30,0),"h:mm AM/PM") -> 5:30 AM - 6:00 AM
A9: =TEXT(TIMEVALUE(LEFT(A8,FIND(" -",A8)-1))+TIME(0,30,0),"h:mm AM/PM")&" - "&TEXT(TIMEVALUE(MID(A8,FIND("- ",A8)+2,99))+TIME(0,30,0),"h:mm AM/PM") -> 6:00 AM - 6:30 AM
A10: =TEXT(TIMEVALUE(LEFT(A9,FIND(" -",A9)-1))+TIME(0,30,0),"h:mm AM/PM")&" - "&TEXT(TIMEVALUE(MID(A9,FIND("- ",A9)+2,99))+TIME(0,30,0),"h:mm AM/PM") -> 6:30 AM - 7:00 AM
A11: =TEXT(TIMEVALUE(LEFT(A10,FIND(" -",A10)-1))+TIME(0,30,0),"h:mm AM/PM")&" - "&TEXT(TIMEVALUE(MID(A10,FIND("- ",A10)+2,99))+TIME(0,30,0),"h:mm AM/PM") -> 7:00 AM - 7:30 AM
A12: =TEXT(TIMEVALUE(LEFT(A11,FIND(" -",A11)-1))+TIME(0,30,0),"h:mm AM/PM")&" - "&TEXT(TIMEVALUE(MID(A11,FIND("- ",A11)+2,99))+TIME(0,30,0),"h:mm AM/PM") -> 7:30 AM - 8:00 AM
A13: =TEXT(TIMEVALUE(LEFT(A12,FIND(" -",A12)-1))+TIME(0,30,0),"h:mm AM/PM")&" - "&TEXT(TIMEVALUE(MID(A12,FIND("- ",A12)+2,99))+TIME(0,30,0),"h:mm AM/PM") -> 8:00 AM - 8:30 AM | F13: 1
A14: =TEXT(TIMEVALUE(LEFT(A13,FIND(" -",A13)-1))+TIME(0,30,0),"h:mm AM/PM")&" - "&TEXT(TIMEVALUE(MID(A13,FIND("- ",A13)+2,99))+TIME(0,30,0),"h:mm AM/PM") -> 8:30 AM - 9:00 AM | F14: 1
A15: =TEXT(TIMEVALUE(LEFT(A14,FIND(" -",A14)-1))+TIME(0,30,0),"h:mm AM/PM")&" - "&TEXT(TIMEVALUE(MID(A14,FIND("- ",A14)+2,99))+TIME(0,30,0),"h:mm AM/PM") -> 9:00 AM - 9:30 AM | B15: 1 | C15: 1 | D15: 1 | E15: 1 | F15: 1
A16: =TEXT(TIMEVALUE(LEFT(A15,FIND(" -",A15)-1))+TIME(0,30,0),"h:mm AM/PM")&" - "&TEXT(TIMEVALUE(MID(A15,FIND("- ",A15)+2,99))+TIME(0,30,0),"h:mm AM/PM") -> 9:30 AM - 10:00 AM | B16: 1 | C16: 1 | D16: 1 | E16: 1 | F16: 1
A17: =TEXT(TIMEVALUE(LEFT(A16,FIND(" -",A16)-1))+TIME(0,30,0),"h:mm AM/PM")&" - "&TEXT(TIMEVALUE(MID(A16,FIND("- ",A16)+2,99))+TIME(0,30,0),"h:mm AM/PM") -> 10:00 AM - 10:30 AM | B17: 1 | C17: 1 | D17: 1 | E17: 1 | F17: 1
A18: =TEXT(TIMEVALUE(LEFT(A17,FIND(" -",A17)-1))+TIME(0,30,0),"h:mm AM/PM")&" - "&TEXT(TIMEVALUE(MID(A17,FIND("- ",A17)+2,99))+TIME(0,30,0),"h:mm AM/PM") -> 10:30 AM - 11:00 AM | B18: 1 | C18: 1 | D18: 1 | E18: 1 | F18: 1
A19: =TEXT(TIMEVALUE(LEFT(A18,FIND(" -",A18)-1))+TIME(0,30,0),"h:mm AM/PM")&" - "&TEXT(TIMEVALUE(MID(A18,FIND("- ",A18)+2,99))+TIME(0,30,0),"h:mm AM/PM") -> 11:00 AM - 11:30 AM | B19: 1 | C19: 1 | D19: 1 | E19: 1 | F19: 1
A20: =TEXT(TIMEVALUE(LEFT(A19,FIND(" -",A19)-1))+TIME(0,30,0),"h:mm AM/PM")&" - "&TEXT(TIMEVALUE(MID(A19,FIND("- ",A19)+2,99))+TIME(0,30,0),"h:mm AM/PM") -> 11:30 AM - 12:00 PM | B20: 1 | C20: 1 | D20: 1 | E20: 1 | F20: 1
A21: =TEXT(TIMEVALUE(LEFT(A20,FIND(" -",A20)-1))+TIME(0,30,0),"h:mm AM/PM")&" - "&TEXT(TIMEVALUE(MID(A20,FIND("- ",A20)+2,99))+TIME(0,30,0),"h:mm AM/PM") -> 12:00 PM - 12:30 PM | B21: 1 | C21: 1 | D21: 1 | E21: 1
A22: =TEXT(TIMEVALUE(LEFT(A21,FIND(" -",A21)-1))+TIME(0,30,0),"h:mm AM/PM")&" - "&TEXT(TIMEVALUE(MID(A21,FIND("- ",A21)+2,99))+TIME(0,30,0),"h:mm AM/PM") -> 12:30 PM - 1:00 PM | B22: 1 | C22: 1 | D22: 1 | E22: 1
A23: =TEXT(TIMEVALUE(LEFT(A22,FIND(" -",A22)-1))+TIME(0,30,0),"h:mm AM/PM")&" - "&TEXT(TIMEVALUE(MID(A22,FIND("- ",A22)+2,99))+TIME(0,30,0),"h:mm AM/PM") -> 1:00 PM - 1:30 PM | C23: 1 | E23: 1
A24: =TEXT(TIMEVALUE(LEFT(A23,FIND(" -",A23)-1))+TIME(0,30,0),"h:mm AM/PM")&" - "&TEXT(TIMEVALUE(MID(A23,FIND("- ",A23)+2,99))+TIME(0,30,0),"h:mm AM/PM") -> 1:30 PM - 2:00 PM | C24: 1 | E24: 1
A25: =TEXT(TIMEVALUE(LEFT(A24,FIND(" -",A24)-1))+TIME(0,30,0),"h:mm AM/PM")&" - "&TEXT(TIMEVALUE(MID(A24,FIND("- ",A24)+2,99))+TIME(0,30,0),"h:mm AM/PM") -> 2:00 PM - 2:30 PM | C25: 1
A26: =TEXT(TIMEVALUE(LEFT(A25,FIND(" -",A25)-1))+TIME(0,30,0),"h:mm AM/PM")&" - "&TEXT(TIMEVALUE(MID(A25,FIND("- ",A25)+2,99))+TIME(0,30,0),"h:mm AM/PM") -> 2:30 PM - 3:00 PM | C26: 1
A27: =TEXT(TIMEVALUE(LEFT(A26,FIND(" -",A26)-1))+TIME(0,30,0),"h:mm AM/PM")&" - "&TEXT(TIMEVALUE(MID(A26,FIND("- ",A26)+2,99))+TIME(0,30,0),"h:mm AM/PM") -> 3:00 PM - 3:30 PM | C27: 1
A28: =TEXT(TIMEVALUE(LEFT(A27,FIND(" -",A27)-1))+TIME(0,30,0),"h:mm AM/PM")&" - "&TEXT(TIMEVALUE(MID(A27,FIND("- ",A27)+2,99))+TIME(0,30,0),"h:mm AM/PM") -> 3:30 PM - 4:00 PM | C28: 1
A29: =TEXT(TIMEVALUE(LEFT(A28,FIND(" -",A28)-1))+TIME(0,30,0),"h:mm AM/PM")&" - "&TEXT(TIMEVALUE(MID(A28,FIND("- ",A28)+2,99))+TIME(0,30,0),"h:mm AM/PM") -> 4:00 PM - 4:30 PM | C29: 1
A30: =TEXT(TIMEVALUE(LEFT(A29,FIND(" -",A29)-1))+TIME(0,30,0),"h:mm AM/PM")&" - "&TEXT(TIMEVALUE(MID(A29,FIND("- ",A29)+2,99))+TIME(0,30,0),"h:mm AM/PM") -> 4:30 PM - 5:00 PM
A31: =TEXT(TIMEVALUE(LEFT(A30,FIND(" -",A30)-1))+TIME(0,30,0),"h:mm AM/PM")&" - "&TEXT(TIMEVALUE(MID(A30,FIND("- ",A30)+2,99))+TIME(0,30,0),"h:mm AM/PM") -> 5:00 PM - 5:30 PM
A32: =TEXT(TIMEVALUE(LEFT(A31,FIND(" -",A31)-1))+TIME(0,30,0),"h:mm AM/PM")&" - "&TEXT(TIMEVALUE(MID(A31,FIND("- ",A31)+2,99))+TIME(0,30,0),"h:mm AM/PM") -> 5:30 PM - 6:00 PM
A33: =TEXT(TIMEVALUE(LEFT(A32,FIND(" -",A32)-1))+TIME(0,30,0),"h:mm AM/PM")&" - "&TEXT(TIMEVALUE(MID(A32,FIND("- ",A32)+2,99))+TIME(0,30,0),"h:mm AM/PM") -> 6:00 PM - 6:30 PM
A34: =TEXT(TIMEVALUE(LEFT(A33,FIND(" -",A33)-1))+TIME(0,30,0),"h:mm AM/PM")&" - "&TEXT(TIMEVALUE(MID(A33,FIND("- ",A33)+2,99))+TIME(0,30,0),"h:mm AM/PM") -> 6:30 PM - 7:00 PM
A35: =TEXT(TIMEVALUE(LEFT(A34,FIND(" -",A34)-1))+TIME(0,30,0),"h:mm AM/PM")&" - "&TEXT(TIMEVALUE(MID(A34,FIND("- ",A34)+2,99))+TIME(0,30,0),"h:mm AM/PM") -> 7:00 PM - 7:30 PM
A36: =TEXT(TIMEVALUE(LEFT(A35,FIND(" -",A35)-1))+TIME(0,30,0),"h:mm AM/PM")&" - "&TEXT(TIMEVALUE(MID(A35,FIND("- ",A35)+2,99))+TIME(0,30,0),"h:mm AM/PM") -> 7:30 PM - 8:00 PM
A37: =TEXT(TIMEVALUE(LEFT(A36,FIND(" -",A36)-1))+TIME(0,30,0),"h:mm AM/PM")&" - "&TEXT(TIMEVALUE(MID(A36,FIND("- ",A36)+2,99))+TIME(0,30,0),"h:mm AM/PM") -> 8:00 PM - 8:30 PM
A38: =TEXT(TIMEVALUE(LEFT(A37,FIND(" -",A37)-1))+TIME(0,30,0),"h:mm AM/PM")&" - "&TEXT(TIMEVALUE(MID(A37,FIND("- ",A37)+2,99))+TIME(0,30,0),"h:mm AM/PM") -> 8:30 PM - 9:00 PM
A39: =TEXT(TIMEVALUE(LEFT(A38,FIND(" -",A38)-1))+TIME(0,30,0),"h:mm AM/PM")&" - "&TEXT(TIMEVALUE(MID(A38,FIND("- ",A38)+2,99))+TIME(0,30,0),"h:mm AM/PM") -> 9:00 PM - 9:30 PM
A40: =TEXT(TIMEVALUE(LEFT(A39,FIND(" -",A39)-1))+TIME(0,30,0),"h:mm AM/PM")&" - "&TEXT(TIMEVALUE(MID(A39,FIND("- ",A39)+2,99))+TIME(0,30,0),"h:mm AM/PM") -> 9:30 PM - 10:00 PM
A41: =TEXT(TIMEVALUE(LEFT(A40,FIND(" -",A40)-1))+TIME(0,30,0),"h:mm AM/PM")&" - "&TEXT(TIMEVALUE(MID(A40,FIND("- ",A40)+2,99))+TIME(0,30,0),"h:mm AM/PM") -> 10:00 PM - 10:30 PM
... A43: =TEXT(TIMEVALUE(LEFT(A42,FIND(" -",A42)-1))+TIME(0,30,0),"h:mm AM/PM")&" - "&TEXT(TIMEVALUE(MID(A42,FIND("- ",A42)+2,99))+TIME(0,30,0),"h:mm AM/PM") -> 11:00 PM - 11:30 PM

Sheet Member 5 Name
A1: Step 1: Rename the sheet name with your name, for example 'Member 5 Name' to 'Your Name' | J1: Time Zone
A2: Step 2: Choose your time zone from yellow drop down box | J2: PST
A3: Step 3: Enter '1' in all 30-minute slots you're NOT available in orange area | J3: {=_xlfn.SWITCH(J2,"PST",0,"MST",1,"CST",2,"EST",3,0)} -> 0
A6: Time | B6: Monday | C6: Tuesday | D6: Wednesday | E6: Thursday | F6: Friday | G6: Saturday | H6: Sunday
A7: =TEXT(TIME(3,0,0)+$J$3/24,"h:mm AM/PM")&" - "&TEXT(TIME(3,30,0)+$J$3/24,"h:mm AM/PM") -> 3:00 AM - 3:30 AM
A8: =TEXT(TIMEVALUE(LEFT(A7,FIND(" -",A7)-1))+TIME(0,30,0),"h:mm AM/PM")&" - "&TEXT(TIMEVALUE(MID(A7,FIND("- ",A7)+2,99))+TIME(0,30,0),"h:mm AM/PM") -> 3:30 AM - 4:00 AM
A9: =TEXT(TIMEVALUE(LEFT(A8,FIND(" -",A8)-1))+TIME(0,30,0),"h:mm AM/PM")&" - "&TEXT(TIMEVALUE(MID(A8,FIND("- ",A8)+2,99))+TIME(0,30,0),"h:mm AM/PM") -> 4:00 AM - 4:30 AM
A10: =TEXT(TIMEVALUE(LEFT(A9,FIND(" -",A9)-1))+TIME(0,30,0),"h:mm AM/PM")&" - "&TEXT(TIMEVALUE(MID(A9,FIND("- ",A9)+2,99))+TIME(0,30,0),"h:mm AM/PM") -> 4:30 AM - 5:00 AM
A11: =TEXT(TIMEVALUE(LEFT(A10,FIND(" -",A10)-1))+TIME(0,30,0),"h:mm AM/PM")&" - "&TEXT(TIMEVALUE(MID(A10,FIND("- ",A10)+2,99))+TIME(0,30,0),"h:mm AM/PM") -> 5:00 AM - 5:30 AM
A12: =TEXT(TIMEVALUE(LEFT(A11,FIND(" -",A11)-1))+TIME(0,30,0),"h:mm AM/PM")&" - "&TEXT(TIMEVALUE(MID(A11,FIND("- ",A11)+2,99))+TIME(0,30,0),"h:mm AM/PM") -> 5:30 AM - 6:00 AM
A13: =TEXT(TIMEVALUE(LEFT(A12,FIND(" -",A12)-1))+TIME(0,30,0),"h:mm AM/PM")&" - "&TEXT(TIMEVALUE(MID(A12,FIND("- ",A12)+2,99))+TIME(0,30,0),"h:mm AM/PM") -> 6:00 AM - 6:30 AM
A14: =TEXT(TIMEVALUE(LEFT(A13,FIND(" -",A13)-1))+TIME(0,30,0),"h:mm AM/PM")&" - "&TEXT(TIMEVALUE(MID(A13,FIND("- ",A13)+2,99))+TIME(0,30,0),"h:mm AM/PM") -> 6:30 AM - 7:00 AM
A15: =TEXT(TIMEVALUE(LEFT(A14,FIND(" -",A14)-1))+TIME(0,30,0),"h:mm AM/PM")&" - "&TEXT(TIMEVALUE(MID(A14,FIND("- ",A14)+2,99))+TIME(0,30,0),"h:mm AM/PM") -> 7:00 AM - 7:30 AM
A16: =TEXT(TIMEVALUE(LEFT(A15,FIND(" -",A15)-1))+TIME(0,30,0),"h:mm AM/PM")&" - "&TEXT(TIMEVALUE(MID(A15,FIND("- ",A15)+2,99))+TIME(0,30,0),"h:mm AM/PM") -> 7:30 AM - 8:00 AM
A17: =TEXT(TIMEVALUE(LEFT(A16,FIND(" -",A16)-1))+TIME(0,30,0),"h:mm AM/PM")&" - "&TEXT(TIMEVALUE(MID(A16,FIND("- ",A16)+2,99))+TIME(0,30,0),"h:mm AM/PM") -> 8:00 AM - 8:30 AM
A18: =TEXT(TIMEVALUE(LEFT(A17,FIND(" -",A17)-1))+TIME(0,30,0),"h:mm AM/PM")&" - "&TEXT(TIMEVALUE(MID(A17,FIND("- ",A17)+2,99))+TIME(0,30,0),"h:mm AM/PM") -> 8:30 AM - 9:00 AM
A19: =TEXT(TIMEVALUE(LEFT(A18,FIND(" -",A18)-1))+TIME(0,30,0),"h:mm AM/PM")&" - "&TEXT(TIMEVALUE(MID(A18,FIND("- ",A18)+2,99))+TIME(0,30,0),"h:mm AM/PM") -> 9:00 AM - 9:30 AM
... A43: =TEXT(TIMEVALUE(LEFT(A42,FIND(" -",A42)-1))+TIME(0,30,0),"h:mm AM/PM")&" - "&TEXT(TIMEVALUE(MID(A42,FIND("- ",A42)+2,99))+TIME(0,30,0),"h:mm AM/PM") -> 9:00 PM - 9:30 PM

Sheet Member 6 Name
A1: Step 1: Rename the sheet name with your name, for example 'Member 5 Name' to 'Your Name' | J1: Time Zone
A2: Step 2: Choose your time zone from yellow drop down box | J2: PST
A3: Step 3: Enter '1' in all 30-minute slots you're NOT available in orange area | J3: {=_xlfn.SWITCH(J2,"PST",0,"MST",1,"CST",2,"EST",3,0)} -> 0
A6: Time | B6: Monday | C6: Tuesday | D6: Wednesday | E6: Thursday | F6: Friday | G6: Saturday | H6: Sunday
A7: =TEXT(TIME(3,0,0)+$J$3/24,"h:mm AM/PM")&" - "&TEXT(TIME(3,30,0)+$J$3/24,"h:mm AM/PM") -> 3:00 AM - 3:30 AM
A8: =TEXT(TIMEVALUE(LEFT(A7,FIND(" -",A7)-1))+TIME(0,30,0),"h:mm AM/PM")&" - "&TEXT(TIMEVALUE(MID(A7,FIND("- ",A7)+2,99))+TIME(0,30,0),"h:mm AM/PM") -> 3:30 AM - 4:00 AM
A9: =TEXT(TIMEVALUE(LEFT(A8,FIND(" -",A8)-1))+TIME(0,30,0),"h:mm AM/PM")&" - "&TEXT(TIMEVALUE(MID(A8,FIND("- ",A8)+2,99))+TIME(0,30,0),"h:mm AM/PM") -> 4:00 AM - 4:30 AM
A10: =TEXT(TIMEVALUE(LEFT(A9,FIND(" -",A9)-1))+TIME(0,30,0),"h:mm AM/PM")&" - "&TEXT(TIMEVALUE(MID(A9,FIND("- ",A9)+2,99))+TIME(0,30,0),"h:mm AM/PM") -> 4:30 AM - 5:00 AM
A11: =TEXT(TIMEVALUE(LEFT(A10,FIND(" -",A10)-1))+TIME(0,30,0),"h:mm AM/PM")&" - "&TEXT(TIMEVALUE(MID(A10,FIND("- ",A10)+2,99))+TIME(0,30,0),"h:mm AM/PM") -> 5:00 AM - 5:30 AM
A12: =TEXT(TIMEVALUE(LEFT(A11,FIND(" -",A11)-1))+TIME(0,30,0),"h:mm AM/PM")&" - "&TEXT(TIMEVALUE(MID(A11,FIND("- ",A11)+2,99))+TIME(0,30,0),"h:mm AM/PM") -> 5:30 AM - 6:00 AM
A13: =TEXT(TIMEVALUE(LEFT(A12,FIND(" -",A12)-1))+TIME(0,30,0),"h:mm AM/PM")&" - "&TEXT(TIMEVALUE(MID(A12,FIND("- ",A12)+2,99))+TIME(0,30,0),"h:mm AM/PM") -> 6:00 AM - 6:30 AM
A14: =TEXT(TIMEVALUE(LEFT(A13,FIND(" -",A13)-1))+TIME(0,30,0),"h:mm AM/PM")&" - "&TEXT(TIMEVALUE(MID(A13,FIND("- ",A13)+2,99))+TIME(0,30,0),"h:mm AM/PM") -> 6:30 AM - 7:00 AM
A15: =TEXT(TIMEVALUE(LEFT(A14,FIND(" -",A14)-1))+TIME(0,30,0),"h:mm AM/PM")&" - "&TEXT(TIMEVALUE(MID(A14,FIND("- ",A14)+2,99))+TIME(0,30,0),"h:mm AM/PM") -> 7:00 AM - 7:30 AM
A16: =TEXT(TIMEVALUE(LEFT(A15,FIND(" -",A15)-1))+TIME(0,30,0),"h:mm AM/PM")&" - "&TEXT(TIMEVALUE(MID(A15,FIND("- ",A15)+2,99))+TIME(0,30,0),"h:mm AM/PM") -> 7:30 AM - 8:00 AM
A17: =TEXT(TIMEVALUE(LEFT(A16,FIND(" -",A16)-1))+TIME(0,30,0),"h:mm AM/PM")&" - "&TEXT(TIMEVALUE(MID(A16,FIND("- ",A16)+2,99))+TIME(0,30,0),"h:mm AM/PM") -> 8:00 AM - 8:30 AM
A18: =TEXT(TIMEVALUE(LEFT(A17,FIND(" -",A17)-1))+TIME(0,30,0),"h:mm AM/PM")&" - "&TEXT(TIMEVALUE(MID(A17,FIND("- ",A17)+2,99))+TIME(0,30,0),"h:mm AM/PM") -> 8:30 AM - 9:00 AM
A19: =TEXT(TIMEVALUE(LEFT(A18,FIND(" -",A18)-1))+TIME(0,30,0),"h:mm AM/PM")&" - "&TEXT(TIMEVALUE(MID(A18,FIND("- ",A18)+2,99))+TIME(0,30,0),"h:mm AM/PM") -> 9:00 AM - 9:30 AM
... A43: =TEXT(TIMEVALUE(LEFT(A42,FIND(" -",A42)-1))+TIME(0,30,0),"h:mm AM/PM")&" - "&TEXT(TIMEVALUE(MID(A42,FIND("- ",A42)+2,99))+TIME(0,30,0),"h:mm AM/PM") -> 9:00 PM - 9:30 PM

Sheet Member 7 Name
A1: Step 1: Rename the sheet name with your name, for example 'Member 5 Name' to 'Your Name' | J1: Time Zone
A2: Step 2: Choose your time zone from yellow drop down box | J2: PST
A3: Step 3: Enter '1' in all 30-minute slots you're NOT available in orange area | J3: {=_xlfn.SWITCH(J2,"PST",0,"MST",1,"CST",2,"EST",3,0)} -> 0
A6: Time | B6: Monday | C6: Tuesday | D6: Wednesday | E6: Thursday | F6: Friday | G6: Saturday | H6: Sunday
A7: =TEXT(TIME(3,0,0)+$J$3/24,"h:mm AM/PM")&" - "&TEXT(TIME(3,30,0)+$J$3/24,"h:mm AM/PM") -> 3:00 AM - 3:30 AM
A8: =TEXT(TIMEVALUE(LEFT(A7,FIND(" -",A7)-1))+TIME(0,30,0),"h:mm AM/PM")&" - "&TEXT(TIMEVALUE(MID(A7,FIND("- ",A7)+2,99))+TIME(0,30,0),"h:mm AM/PM") -> 3:30 AM - 4:00 AM
A9: =TEXT(TIMEVALUE(LEFT(A8,FIND(" -",A8)-1))+TIME(0,30,0),"h:mm AM/PM")&" - "&TEXT(TIMEVALUE(MID(A8,FIND("- ",A8)+2,99))+TIME(0,30,0),"h:mm AM/PM") -> 4:00 AM - 4:30 AM
A10: =TEXT(TIMEVALUE(LEFT(A9,FIND(" -",A9)-1))+TIME(0,30,0),"h:mm AM/PM")&" - "&TEXT(TIMEVALUE(MID(A9,FIND("- ",A9)+2,99))+TIME(0,30,0),"h:mm AM/PM") -> 4:30 AM - 5:00 AM
A11: =TEXT(TIMEVALUE(LEFT(A10,FIND(" -",A10)-1))+TIME(0,30,0),"h:mm AM/PM")&" - "&TEXT(TIMEVALUE(MID(A10,FIND("- ",A10)+2,99))+TIME(0,30,0),"h:mm AM/PM") -> 5:00 AM - 5:30 AM
A12: =TEXT(TIMEVALUE(LEFT(A11,FIND(" -",A11)-1))+TIME(0,30,0),"h:mm AM/PM")&" - "&TEXT(TIMEVALUE(MID(A11,FIND("- ",A11)+2,99))+TIME(0,30,0),"h:mm AM/PM") -> 5:30 AM - 6:00 AM
A13: =TEXT(TIMEVALUE(LEFT(A12,FIND(" -",A12)-1))+TIME(0,30,0),"h:mm AM/PM")&" - "&TEXT(TIMEVALUE(MID(A12,FIND("- ",A12)+2,99))+TIME(0,30,0),"h:mm AM/PM") -> 6:00 AM - 6:30 AM
A14: =TEXT(TIMEVALUE(LEFT(A13,FIND(" -",A13)-1))+TIME(0,30,0),"h:mm AM/PM")&" - "&TEXT(TIMEVALUE(MID(A13,FIND("- ",A13)+2,99))+TIME(0,30,0),"h:mm AM/PM") -> 6:30 AM - 7:00 AM
A15: =TEXT(TIMEVALUE(LEFT(A14,FIND(" -",A14)-1))+TIME(0,30,0),"h:mm AM/PM")&" - "&TEXT(TIMEVALUE(MID(A14,FIND("- ",A14)+2,99))+TIME(0,30,0),"h:mm AM/PM") -> 7:00 AM - 7:30 AM
A16: =TEXT(TIMEVALUE(LEFT(A15,FIND(" -",A15)-1))+TIME(0,30,0),"h:mm AM/PM")&" - "&TEXT(TIMEVALUE(MID(A15,FIND("- ",A15)+2,99))+TIME(0,30,0),"h:mm AM/PM") -> 7:30 AM - 8:00 AM
A17: =TEXT(TIMEVALUE(LEFT(A16,FIND(" -",A16)-1))+TIME(0,30,0),"h:mm AM/PM")&" - "&TEXT(TIMEVALUE(MID(A16,FIND("- ",A16)+2,99))+TIME(0,30,0),"h:mm AM/PM") -> 8:00 AM - 8:30 AM
A18: =TEXT(TIMEVALUE(LEFT(A17,FIND(" -",A17)-1))+TIME(0,30,0),"h:mm AM/PM")&" - "&TEXT(TIMEVALUE(MID(A17,FIND("- ",A17)+2,99))+TIME(0,30,0),"h:mm AM/PM") -> 8:30 AM - 9:00 AM
A19: =TEXT(TIMEVALUE(LEFT(A18,FIND(" -",A18)-1))+TIME(0,30,0),"h:mm AM/PM")&" - "&TEXT(TIMEVALUE(MID(A18,FIND("- ",A18)+2,99))+TIME(0,30,0),"h:mm AM/PM") -> 9:00 AM - 9:30 AM
... A43: =TEXT(TIMEVALUE(LEFT(A42,FIND(" -",A42)-1))+TIME(0,30,0),"h:mm AM/PM")&" - "&TEXT(TIMEVALUE(MID(A42,FIND("- ",A42)+2,99))+TIME(0,30,0),"h:mm AM/PM") -> 9:00 PM - 9:30 PM

Sheet Team Availability
A1: Step 1. Choose your time zone from yellow drop down box | J1: Time Zone
J2: PST
A3: The darker the cell, the more people are available. Black cells mean all members are free to meet. | J3: {=_xlfn.SWITCH(J2,"PST",0,"MST",1,"CST",2,"EST",3,0)} -> 0
A6: Time | B6: Monday | C6: Tuesday | D6: Wednesday | E6: Thursday | F6: Friday | G6: Saturday | H6: Sunday
A7: =TEXT(TIME(3,0,0)+$J$3/24,"h:mm AM/PM")&" - "&TEXT(TIME(3,30,0)+$J$3/24,"h:mm AM/PM") -> 3:00 AM - 3:30 AM | B7: =IF(COUNTA('Lisa Zhou'!B7,'Colin Hui'!B7,'Iris Liu'!B7,'Max McCarter'!B7,'Member 5 Name'!B7,'Member 6 Name'!B7,'Member 7 Name'!B7)=0,0,COUNTA('Lisa Zhou'!B7,'Colin Hui'!B7,'Iris Liu'!B7,'Max McCarter'!B7,'Member 5 Name'!B7,'Member 6 Name'!B7,'Member 7 Name'!B7)) -> 2 | C7: =IF(COUNTA('Lisa Zhou'!C7,'Colin Hui'!C7,'Iris Liu'!C7,'Max McCarter'!C7,'Member 5 Name'!C7,'Member 6 Name'!C7,'Member 7 Name'!C7)=0,0,COUNTA('Lisa Zhou'!C7,'Colin Hui'!C7,'Iris Liu'!C7,'Max McCarter'!C7,'Member 5 Name'!C7,'Member 6 Name'!C7,'Member 7 Name'!C7)) -> 2 | D7: =IF(COUNTA('Lisa Zhou'!D7,'Colin Hui'!D7,'Iris Liu'!D7,'Max McCarter'!D7,'Member 5 Name'!D7,'Member 6 Name'!D7,'Member 7 Name'!D7)=0,0,COUNTA('Lisa Zhou'!D7,'Colin Hui'!D7,'Iris Liu'!D7,'Max McCarter'!D7,'Member 5 Name'!D7,'Member 6 Name'!D7,'Member 7 Name'!D7)) -> 2 | E7: =IF(COUNTA('Lisa Zhou'!E7,'Colin Hui'!E7,'Iris Liu'!E7,'Max McCarter'!E7,'Member 5 Name'!E7,'Member 6 Name'!E7,'Member 7 Name'!E7)=0,0,COUNTA('Lisa Zhou'!E7,'Colin Hui'!E7,'Iris Liu'!E7,'Max McCarter'!E7,'Member 5 Name'!E7,'Member 6 Name'!E7,'Member 7 Name'!E7)) -> 2 | F7: =IF(COUNTA('Lisa Zhou'!F7,'Colin Hui'!F7,'Iris Liu'!F7,'Max McCarter'!F7,'Member 5 Name'!F7,'Member 6 Name'!F7,'Member 7 Name'!F7)=0,0,COUNTA('Lisa Zhou'!F7,'Colin Hui'!F7,'Iris Liu'!F7,'Max McCarter'!F7,'Member 5 Name'!F7,'Member 6 Name'!F7,'Member 7 Name'!F7)) -> 2 | G7: =IF(COUNTA('Lisa Zhou'!G7,'Colin Hui'!G7,'Iris Liu'!G7,'Max McCarter'!G7,'Member 5 Name'!G7,'Member 6 Name'!G7,'Member 7 Name'!G7)=0,0,COUNTA('Lisa Zhou'!G7,'Colin Hui'!G7,'Iris Liu'!G7,'Max McCarter'!G7,'Member 5 Name'!G7,'Member 6 Name'!G7,'Member 7 Name'!G7)) -> 2 | H7: =IF(COUNTA('Lisa Zhou'!H7,'Colin Hui'!H7,'Iris Liu'!H7,'Max McCarter'!H7,'Member 5 Name'!H7,'Member 6 Name'!H7,'Member 7 Name'!H7)=0,0,COUNTA('Lisa Zhou'!H7,'Colin Hui'!H7,'Iris Liu'!H7,'Max McCarter'!H7,'Member 5 Name'!H7,'Member 6 Name'!H7,'Member 7 Name'!H7)) -> 2
A8: =TEXT(TIMEVALUE(LEFT(A7,FIND(" -",A7)-1))+TIME(0,30,0),"h:mm AM/PM")&" - "&TEXT(TIMEVALUE(MID(A7,FIND("- ",A7)+2,99))+TIME(0,30,0),"h:mm AM/PM") -> 3:30 AM - 4:00 AM | B8: =IF(COUNTA('Lisa Zhou'!B8,'Colin Hui'!B8,'Iris Liu'!B8,'Max McCarter'!B8,'Member 5 Name'!B8,'Member 6 Name'!B8,'Member 7 Name'!B8)=0,0,COUNTA('Lisa Zhou'!B8,'Colin Hui'!B8,'Iris Liu'!B8,'Max McCarter'!B8,'Member 5 Name'!B8,'Member 6 Name'!B8,'Member 7 Name'!B8)) -> 2 | C8: =IF(COUNTA('Lisa Zhou'!C8,'Colin Hui'!C8,'Iris Liu'!C8,'Max McCarter'!C8,'Member 5 Name'!C8,'Member 6 Name'!C8,'Member 7 Name'!C8)=0,0,COUNTA('Lisa Zhou'!C8,'Colin Hui'!C8,'Iris Liu'!C8,'Max McCarter'!C8,'Member 5 Name'!C8,'Member 6 Name'!C8,'Member 7 Name'!C8)) -> 2 | D8: =IF(COUNTA('Lisa Zhou'!D8,'Colin Hui'!D8,'Iris Liu'!D8,'Max McCarter'!D8,'Member 5 Name'!D8,'Member 6 Name'!D8,'Member 7 Name'!D8)=0,0,COUNTA('Lisa Zhou'!D8,'Colin Hui'!D8,'Iris Liu'!D8,'Max McCarter'!D8,'Member 5 Name'!D8,'Member 6 Name'!D8,'Member 7 Name'!D8)) -> 2 | E8: =IF(COUNTA('Lisa Zhou'!E8,'Colin Hui'!E8,'Iris Liu'!E8,'Max McCarter'!E8,'Member 5 Name'!E8,'Member 6 Name'!E8,'Member 7 Name'!E8)=0,0,COUNTA('Lisa Zhou'!E8,'Colin Hui'!E8,'Iris Liu'!E8,'Max McCarter'!E8,'Member 5 Name'!E8,'Member 6 Name'!E8,'Member 7 Name'!E8)) -> 2 | F8: =IF(COUNTA('Lisa Zhou'!F8,'Colin Hui'!F8,'Iris Liu'!F8,'Max McCarter'!F8,'Member 5 Name'!F8,'Member 6 Name'!F8,'Member 7 Name'!F8)=0,0,COUNTA('Lisa Zhou'!F8,'Colin Hui'!F8,'Iris Liu'!F8,'Max McCarter'!F8,'Member 5 Name'!F8,'Member 6 Name'!F8,'Member 7 Name'!F8)) -> 2 | G8: =IF(COUNTA('Lisa Zhou'!G8,'Colin Hui'!G8,'Iris Liu'!G8,'Max McCarter'!G8,'Member 5 Name'!G8,'Member 6 Name'!G8,'Member 7 Name'!G8)=0,0,COUNTA('Lisa Zhou'!G8,'Colin Hui'!G8,'Iris Liu'!G8,'Max McCarter'!G8,'Member 5 Name'!G8,'Member 6 Name'!G8,'Member 7 Name'!G8)) -> 2 | H8: =IF(COUNTA('Lisa Zhou'!H8,'Colin Hui'!H8,'Iris Liu'!H8,'Max McCarter'!H8,'Member 5 Name'!H8,'Member 6 Name'!H8,'Member 7 Name'!H8)=0,0,COUNTA('Lisa Zhou'!H8,'Colin Hui'!H8,'Iris Liu'!H8,'Max McCarter'!H8,'Member 5 Name'!H8,'Member 6 Name'!H8,'Member 7 Name'!H8)) -> 2
A9: =TEXT(TIMEVALUE(LEFT(A8,FIND(" -",A8)-1))+TIME(0,30,0),"h:mm AM/PM")&" - "&TEXT(TIMEVALUE(MID(A8,FIND("- ",A8)+2,99))+TIME(0,30,0),"h:mm AM/PM") -> 4:00 AM - 4:30 AM | B9: =IF(COUNTA('Lisa Zhou'!B9,'Colin Hui'!B9,'Iris Liu'!B9,'Max McCarter'!B9,'Member 5 Name'!B9,'Member 6 Name'!B9,'Member 7 Name'!B9)=0,0,COUNTA('Lisa Zhou'!B9,'Colin Hui'!B9,'Iris Liu'!B9,'Max McCarter'!B9,'Member 5 Name'!B9,'Member 6 Name'!B9,'Member 7 Name'!B9)) -> 2 | C9: =IF(COUNTA('Lisa Zhou'!C9,'Colin Hui'!C9,'Iris Liu'!C9,'Max McCarter'!C9,'Member 5 Name'!C9,'Member 6 Name'!C9,'Member 7 Name'!C9)=0,0,COUNTA('Lisa Zhou'!C9,'Colin Hui'!C9,'Iris Liu'!C9,'Max McCarter'!C9,'Member 5 Name'!C9,'Member 6 Name'!C9,'Member 7 Name'!C9)) -> 2 | D9: =IF(COUNTA('Lisa Zhou'!D9,'Colin Hui'!D9,'Iris Liu'!D9,'Max McCarter'!D9,'Member 5 Name'!D9,'Member 6 Name'!D9,'Member 7 Name'!D9)=0,0,COUNTA('Lisa Zhou'!D9,'Colin Hui'!D9,'Iris Liu'!D9,'Max McCarter'!D9,'Member 5 Name'!D9,'Member 6 Name'!D9,'Member 7 Name'!D9)) -> 2 | E9: =IF(COUNTA('Lisa Zhou'!E9,'Colin Hui'!E9,'Iris Liu'!E9,'Max McCarter'!E9,'Member 5 Name'!E9,'Member 6 Name'!E9,'Member 7 Name'!E9)=0,0,COUNTA('Lisa Zhou'!E9,'Colin Hui'!E9,'Iris Liu'!E9,'Max McCarter'!E9,'Member 5 Name'!E9,'Member 6 Name'!E9,'Member 7 Name'!E9)) -> 2 | F9: =IF(COUNTA('Lisa Zhou'!F9,'Colin Hui'!F9,'Iris Liu'!F9,'Max McCarter'!F9,'Member 5 Name'!F9,'Member 6 Name'!F9,'Member 7 Name'!F9)=0,0,COUNTA('Lisa Zhou'!F9,'Colin Hui'!F9,'Iris Liu'!F9,'Max McCarter'!F9,'Member 5 Name'!F9,'Member 6 Name'!F9,'Member 7 Name'!F9)) -> 2 | G9: =IF(COUNTA('Lisa Zhou'!G9,'Colin Hui'!G9,'Iris Liu'!G9,'Max McCarter'!G9,'Member 5 Name'!G9,'Member 6 Name'!G9,'Member 7 Name'!G9)=0,0,COUNTA('Lisa Zhou'!G9,'Colin Hui'!G9,'Iris Liu'!G9,'Max McCarter'!G9,'Member 5 Name'!G9,'Member 6 Name'!G9,'Member 7 Name'!G9)) -> 2 | H9: =IF(COUNTA('Lisa Zhou'!H9,'Colin Hui'!H9,'Iris Liu'!H9,'Max McCarter'!H9,'Member 5 Name'!H9,'Member 6 Name'!H9,'Member 7 Name'!H9)=0,0,COUNTA('Lisa Zhou'!H9,'Colin Hui'!H9,'Iris Liu'!H9,'Max McCarter'!H9,'Member 5 Name'!H9,'Member 6 Name'!H9,'Member 7 Name'!H9)) -> 2
A10: =TEXT(TIMEVALUE(LEFT(A9,FIND(" -",A9)-1))+TIME(0,30,0),"h:mm AM/PM")&" - "&TEXT(TIMEVALUE(MID(A9,FIND("- ",A9)+2,99))+TIME(0,30,0),"h:mm AM/PM") -> 4:30 AM - 5:00 AM | B10: =IF(COUNTA('Lisa Zhou'!B10,'Colin Hui'!B10,'Iris Liu'!B10,'Max McCarter'!B10,'Member 5 Name'!B10,'Member 6 Name'!B10,'Member 7 Name'!B10)=0,0,COUNTA('Lisa Zhou'!B10,'Colin Hui'!B10,'Iris Liu'!B10,'Max McCarter'!B10,'Member 5 Name'!B10,'Member 6 Name'!B10,'Member 7 Name'!B10)) -> 2 | C10: =IF(COUNTA('Lisa Zhou'!C10,'Colin Hui'!C10,'Iris Liu'!C10,'Max McCarter'!C10,'Member 5 Name'!C10,'Member 6 Name'!C10,'Member 7 Name'!C10)=0,0,COUNTA('Lisa Zhou'!C10,'Colin Hui'!C10,'Iris Liu'!C10,'Max McCarter'!C10,'Member 5 Name'!C10,'Member 6 Name'!C10,'Member 7 Name'!C10)) -> 2 | D10: =IF(COUNTA('Lisa Zhou'!D10,'Colin Hui'!D10,'Iris Liu'!D10,'Max McCarter'!D10,'Member 5 Name'!D10,'Member 6 Name'!D10,'Member 7 Name'!D10)=0,0,COUNTA('Lisa Zhou'!D10,'Colin Hui'!D10,'Iris Liu'!D10,'Max McCarter'!D10,'Member 5 Name'!D10,'Member 6 Name'!D10,'Member 7 Name'!D10)) -> 2 | E10: =IF(COUNTA('Lisa Zhou'!E10,'Colin Hui'!E10,'Iris Liu'!E10,'Max McCarter'!E10,'Member 5 Name'!E10,'Member 6 Name'!E10,'Member 7 Name'!E10)=0,0,COUNTA('Lisa Zhou'!E10,'Colin Hui'!E10,'Iris Liu'!E10,'Max McCarter'!E10,'Member 5 Name'!E10,'Member 6 Name'!E10,'Member 7 Name'!E10)) -> 2 | F10: =IF(COUNTA('Lisa Zhou'!F10,'Colin Hui'!F10,'Iris Liu'!F10,'Max McCarter'!F10,'Member 5 Name'!F10,'Member 6 Name'!F10,'Member 7 Name'!F10)=0,0,COUNTA('Lisa Zhou'!F10,'Colin Hui'!F10,'Iris Liu'!F10,'Max McCarter'!F10,'Member 5 Name'!F10,'Member 6 Name'!F10,'Member 7 Name'!F10)) -> 2 | G10: =IF(COUNTA('Lisa Zhou'!G10,'Colin Hui'!G10,'Iris Liu'!G10,'Max McCarter'!G10,'Member 5 Name'!G10,'Member 6 Name'!G10,'Member 7 Name'!G10)=0,0,COUNTA('Lisa Zhou'!G10,'Colin Hui'!G10,'Iris Liu'!G10,'Max McCarter'!G10,'Member 5 Name'!G10,'Member 6 Name'!G10,'Member 7 Name'!G10)) -> 2 | H10: =IF(COUNTA('Lisa Zhou'!H10,'Colin Hui'!H10,'Iris Liu'!H10,'Max McCarter'!H10,'Member 5 Name'!H10,'Member 6 Name'!H10,'Member 7 Name'!H10)=0,0,COUNTA('Lisa Zhou'!H10,'Colin Hui'!H10,'Iris Liu'!H10,'Max McCarter'!H10,'Member 5 Name'!H10,'Member 6 Name'!H10,'Member 7 Name'!H10)) -> 2
A11: =TEXT(TIMEVALUE(LEFT(A10,FIND(" -",A10)-1))+TIME(0,30,0),"h:mm AM/PM")&" - "&TEXT(TIMEVALUE(MID(A10,FIND("- ",A10)+2,99))+TIME(0,30,0),"h:mm AM/PM") -> 5:00 AM - 5:30 AM | B11: =IF(COUNTA('Lisa Zhou'!B11,'Colin Hui'!B11,'Iris Liu'!B11,'Max McCarter'!B11,'Member 5 Name'!B11,'Member 6 Name'!B11,'Member 7 Name'!B11)=0,0,COUNTA('Lisa Zhou'!B11,'Colin Hui'!B11,'Iris Liu'!B11,'Max McCarter'!B11,'Member 5 Name'!B11,'Member 6 Name'!B11,'Member 7 Name'!B11)) -> 2 | C11: =IF(COUNTA('Lisa Zhou'!C11,'Colin Hui'!C11,'Iris Liu'!C11,'Max McCarter'!C11,'Member 5 Name'!C11,'Member 6 Name'!C11,'Member 7 Name'!C11)=0,0,COUNTA('Lisa Zhou'!C11,'Colin Hui'!C11,'Iris Liu'!C11,'Max McCarter'!C11,'Member 5 Name'!C11,'Member 6 Name'!C11,'Member 7 Name'!C11)) -> 2 | D11: =IF(COUNTA('Lisa Zhou'!D11,'Colin Hui'!D11,'Iris Liu'!D11,'Max McCarter'!D11,'Member 5 Name'!D11,'Member 6 Name'!D11,'Member 7 Name'!D11)=0,0,COUNTA('Lisa Zhou'!D11,'Colin Hui'!D11,'Iris Liu'!D11,'Max McCarter'!D11,'Member 5 Name'!D11,'Member 6 Name'!D11,'Member 7 Name'!D11)) -> 2 | E11: =IF(COUNTA('Lisa Zhou'!E11,'Colin Hui'!E11,'Iris Liu'!E11,'Max McCarter'!E11,'Member 5 Name'!E11,'Member 6 Name'!E11,'Member 7 Name'!E11)=0,0,COUNTA('Lisa Zhou'!E11,'Colin Hui'!E11,'Iris Liu'!E11,'Max McCarter'!E11,'Member 5 Name'!E11,'Member 6 Name'!E11,'Member 7 Name'!E11)) -> 2 | F11: =IF(COUNTA('Lisa Zhou'!F11,'Colin Hui'!F11,'Iris Liu'!F11,'Max McCarter'!F11,'Member 5 Name'!F11,'Member 6 Name'!F11,'Member 7 Name'!F11)=0,0,COUNTA('Lisa Zhou'!F11,'Colin Hui'!F11,'Iris Liu'!F11,'Max McCarter'!F11,'Member 5 Name'!F11,'Member 6 Name'!F11,'Member 7 Name'!F11)) -> 2 | G11: =IF(COUNTA('Lisa Zhou'!G11,'Colin Hui'!G11,'Iris Liu'!G11,'Max McCarter'!G11,'Member 5 Name'!G11,'Member 6 Name'!G11,'Member 7 Name'!G11)=0,0,COUNTA('Lisa Zhou'!G11,'Colin Hui'!G11,'Iris Liu'!G11,'Max McCarter'!G11,'Member 5 Name'!G11,'Member 6 Name'!G11,'Member 7 Name'!G11)) -> 2 | H11: =IF(COUNTA('Lisa Zhou'!H11,'Colin Hui'!H11,'Iris Liu'!H11,'Max McCarter'!H11,'Member 5 Name'!H11,'Member 6 Name'!H11,'Member 7 Name'!H11)=0,0,COUNTA('Lisa Zhou'!H11,'Colin Hui'!H11,'Iris Liu'!H11,'Max McCarter'!H11,'Member 5 Name'!H11,'Member 6 Name'!H11,'Member 7 Name'!H11)) -> 2
A12: =TEXT(TIMEVALUE(LEFT(A11,FIND(" -",A11)-1))+TIME(0,30,0),"h:mm AM/PM")&" - "&TEXT(TIMEVALUE(MID(A11,FIND("- ",A11)+2,99))+TIME(0,30,0),"h:mm AM/PM") -> 5:30 AM - 6:00 AM | B12: =IF(COUNTA('Lisa Zhou'!B12,'Colin Hui'!B12,'Iris Liu'!B12,'Max McCarter'!B12,'Member 5 Name'!B12,'Member 6 Name'!B12,'Member 7 Name'!B12)=0,0,COUNTA('Lisa Zhou'!B12,'Colin Hui'!B12,'Iris Liu'!B12,'Max McCarter'!B12,'Member 5 Name'!B12,'Member 6 Name'!B12,'Member 7 Name'!B12)) -> 2 | C12: =IF(COUNTA('Lisa Zhou'!C12,'Colin Hui'!C12,'Iris Liu'!C12,'Max McCarter'!C12,'Member 5 Name'!C12,'Member 6 Name'!C12,'Member 7 Name'!C12)=0,0,COUNTA('Lisa Zhou'!C12,'Colin Hui'!C12,'Iris Liu'!C12,'Max McCarter'!C12,'Member 5 Name'!C12,'Member 6 Name'!C12,'Member 7 Name'!C12)) -> 2 | D12: =IF(COUNTA('Lisa Zhou'!D12,'Colin Hui'!D12,'Iris Liu'!D12,'Max McCarter'!D12,'Member 5 Name'!D12,'Member 6 Name'!D12,'Member 7 Name'!D12)=0,0,COUNTA('Lisa Zhou'!D12,'Colin Hui'!D12,'Iris Liu'!D12,'Max McCarter'!D12,'Member 5 Name'!D12,'Member 6 Name'!D12,'Member 7 Name'!D12)) -> 2 | E12: =IF(COUNTA('Lisa Zhou'!E12,'Colin Hui'!E12,'Iris Liu'!E12,'Max McCarter'!E12,'Member 5 Name'!E12,'Member 6 Name'!E12,'Member 7 Name'!E12)=0,0,COUNTA('Lisa Zhou'!E12,'Colin Hui'!E12,'Iris Liu'!E12,'Max McCarter'!E12,'Member 5 Name'!E12,'Member 6 Name'!E12,'Member 7 Name'!E12)) -> 2 | F12: =IF(COUNTA('Lisa Zhou'!F12,'Colin Hui'!F12,'Iris Liu'!F12,'Max McCarter'!F12,'Member 5 Name'!F12,'Member 6 Name'!F12,'Member 7 Name'!F12)=0,0,COUNTA('Lisa Zhou'!F12,'Colin Hui'!F12,'Iris Liu'!F12,'Max McCarter'!F12,'Member 5 Name'!F12,'Member 6 Name'!F12,'Member 7 Name'!F12)) -> 2 | G12: =IF(COUNTA('Lisa Zhou'!G12,'Colin Hui'!G12,'Iris Liu'!G12,'Max McCarter'!G12,'Member 5 Name'!G12,'Member 6 Name'!G12,'Member 7 Name'!G12)=0,0,COUNTA('Lisa Zhou'!G12,'Colin Hui'!G12,'Iris Liu'!G12,'Max McCarter'!G12,'Member 5 Name'!G12,'Member 6 Name'!G12,'Member 7 Name'!G12)) -> 2 | H12: =IF(COUNTA('Lisa Zhou'!H12,'Colin Hui'!H12,'Iris Liu'!H12,'Max McCarter'!H12,'Member 5 Name'!H12,'Member 6 Name'!H12,'Member 7 Name'!H12)=0,0,COUNTA('Lisa Zhou'!H12,'Colin Hui'!H12,'Iris Liu'!H12,'Max McCarter'!H12,'Member 5 Name'!H12,'Member 6 Name'!H12,'Member 7 Name'!H12)) -> 2
A13: =TEXT(TIMEVALUE(LEFT(A12,FIND(" -",A12)-1))+TIME(0,30,0),"h:mm AM/PM")&" - "&TEXT(TIMEVALUE(MID(A12,FIND("- ",A12)+2,99))+TIME(0,30,0),"h:mm AM/PM") -> 6:00 AM - 6:30 AM | B13: =IF(COUNTA('Lisa Zhou'!B13,'Colin Hui'!B13,'Iris Liu'!B13,'Max McCarter'!B13,'Member 5 Name'!B13,'Member 6 Name'!B13,'Member 7 Name'!B13)=0,0,COUNTA('Lisa Zhou'!B13,'Colin Hui'!B13,'Iris Liu'!B13,'Max McCarter'!B13,'Member 5 Name'!B13,'Member 6 Name'!B13,'Member 7 Name'!B13)) -> 2 | C13: =IF(COUNTA('Lisa Zhou'!C13,'Colin Hui'!C13,'Iris Liu'!C13,'Max McCarter'!C13,'Member 5 Name'!C13,'Member 6 Name'!C13,'Member 7 Name'!C13)=0,0,COUNTA('Lisa Zhou'!C13,'Colin Hui'!C13,'Iris Liu'!C13,'Max McCarter'!C13,'Member 5 Name'!C13,'Member 6 Name'!C13,'Member 7 Name'!C13)) -> 2 | D13: =IF(COUNTA('Lisa Zhou'!D13,'Colin Hui'!D13,'Iris Liu'!D13,'Max McCarter'!D13,'Member 5 Name'!D13,'Member 6 Name'!D13,'Member 7 Name'!D13)=0,0,COUNTA('Lisa Zhou'!D13,'Colin Hui'!D13,'Iris Liu'!D13,'Max McCarter'!D13,'Member 5 Name'!D13,'Member 6 Name'!D13,'Member 7 Name'!D13)) -> 3 | E13: =IF(COUNTA('Lisa Zhou'!E13,'Colin Hui'!E13,'Iris Liu'!E13,'Max McCarter'!E13,'Member 5 Name'!E13,'Member 6 Name'!E13,'Member 7 Name'!E13)=0,0,COUNTA('Lisa Zhou'!E13,'Colin Hui'!E13,'Iris Liu'!E13,'Max McCarter'!E13,'Member 5 Name'!E13,'Member 6 Name'!E13,'Member 7 Name'!E13)) -> 2 | F13: =IF(COUNTA('Lisa Zhou'!F13,'Colin Hui'!F13,'Iris Liu'!F13,'Max McCarter'!F13,'Member 5 Name'!F13,'Member 6 Name'!F13,'Member 7 Name'!F13)=0,0,COUNTA('Lisa Zhou'!F13,'Colin Hui'!F13,'Iris Liu'!F13,'Max McCarter'!F13,'Member 5 Name'!F13,'Member 6 Name'!F13,'Member 7 Name'!F13)) -> 3 | G13: =IF(COUNTA('Lisa Zhou'!G13,'Colin Hui'!G13,'Iris Liu'!G13,'Max McCarter'!G13,'Member 5 Name'!G13,'Member 6 Name'!G13,'Member 7 Name'!G13)=0,0,COUNTA('Lisa Zhou'!G13,'Colin Hui'!G13,'Iris Liu'!G13,'Max McCarter'!G13,'Member 5 Name'!G13,'Member 6 Name'!G13,'Member 7 Name'!G13)) -> 1 | H13: =IF(COUNTA('Lisa Zhou'!H13,'Colin Hui'!H13,'Iris Liu'!H13,'Max McCarter'!H13,'Member 5 Name'!H13,'Member 6 Name'!H13,'Member 7 Name'!H13)=0,0,COUNTA('Lisa Zhou'!H13,'Colin Hui'!H13,'Iris Liu'!H13,'Max McCarter'!H13,'Member 5 Name'!H13,'Member 6 Name'!H13,'Member 7 Name'!H13)) -> 1
A14: =TEXT(TIMEVALUE(LEFT(A13,FIND(" -",A13)-1))+TIME(0,30,0),"h:mm AM/PM")&" - "&TEXT(TIMEVALUE(MID(A13,FIND("- ",A13)+2,99))+TIME(0,30,0),"h:mm AM/PM") -> 6:30 AM - 7:00 AM | B14: =IF(COUNTA('Lisa Zhou'!B14,'Colin Hui'!B14,'Iris Liu'!B14,'Max McCarter'!B14,'Member 5 Name'!B14,'Member 6 Name'!B14,'Member 7 Name'!B14)=0,0,COUNTA('Lisa Zhou'!B14,'Colin Hui'!B14,'Iris Liu'!B14,'Max McCarter'!B14,'Member 5 Name'!B14,'Member 6 Name'!B14,'Member 7 Name'!B14)) -> 2 | C14: =IF(COUNTA('Lisa Zhou'!C14,'Colin Hui'!C14,'Iris Liu'!C14,'Max McCarter'!C14,'Member 5 Name'!C14,'Member 6 Name'!C14,'Member 7 Name'!C14)=0,0,COUNTA('Lisa Zhou'!C14,'Colin Hui'!C14,'Iris Liu'!C14,'Max McCarter'!C14,'Member 5 Name'!C14,'Member 6 Name'!C14,'Member 7 Name'!C14)) -> 2 | D14: =IF(COUNTA('Lisa Zhou'!D14,'Colin Hui'!D14,'Iris Liu'!D14,'Max McCarter'!D14,'Member 5 Name'!D14,'Member 6 Name'!D14,'Member 7 Name'!D14)=0,0,COUNTA('Lisa Zhou'!D14,'Colin Hui'!D14,'Iris Liu'!D14,'Max McCarter'!D14,'Member 5 Name'!D14,'Member 6 Name'!D14,'Member 7 Name'!D14)) -> 3 | E14: =IF(COUNTA('Lisa Zhou'!E14,'Colin Hui'!E14,'Iris Liu'!E14,'Max McCarter'!E14,'Member 5 Name'!E14,'Member 6 Name'!E14,'Member 7 Name'!E14)=0,0,COUNTA('Lisa Zhou'!E14,'Colin Hui'!E14,'Iris Liu'!E14,'Max McCarter'!E14,'Member 5 Name'!E14,'Member 6 Name'!E14,'Member 7 Name'!E14)) -> 2 | F14: =IF(COUNTA('Lisa Zhou'!F14,'Colin Hui'!F14,'Iris Liu'!F14,'Max McCarter'!F14,'Member 5 Name'!F14,'Member 6 Name'!F14,'Member 7 Name'!F14)=0,0,COUNTA('Lisa Zhou'!F14,'Colin Hui'!F14,'Iris Liu'!F14,'Max McCarter'!F14,'Member 5 Name'!F14,'Member 6 Name'!F14,'Member 7 Name'!F14)) -> 3 | G14: =IF(COUNTA('Lisa Zhou'!G14,'Colin Hui'!G14,'Iris Liu'!G14,'Max McCarter'!G14,'Member 5 Name'!G14,'Member 6 Name'!G14,'Member 7 Name'!G14)=0,0,COUNTA('Lisa Zhou'!G14,'Colin Hui'!G14,'Iris Liu'!G14,'Max McCarter'!G14,'Member 5 Name'!G14,'Member 6 Name'!G14,'Member 7 Name'!G14)) -> 1 | H14: =IF(COUNTA('Lisa Zhou'!H14,'Colin Hui'!H14,'Iris Liu'!H14,'Max McCarter'!H14,'Member 5 Name'!H14,'Member 6 Name'!H14,'Member 7 Name'!H14)=0,0,COUNTA('Lisa Zhou'!H14,'Colin Hui'!H14,'Iris Liu'!H14,'Max McCarter'!H14,'Member 5 Name'!H14,'Member 6 Name'!H14,'Member 7 Name'!H14)) -> 1
A15: =TEXT(TIMEVALUE(LEFT(A14,FIND(" -",A14)-1))+TIME(0,30,0),"h:mm AM/PM")&" - "&TEXT(TIMEVALUE(MID(A14,FIND("- ",A14)+2,99))+TIME(0,30,0),"h:mm AM/PM") -> 7:00 AM - 7:30 AM | B15: =IF(COUNTA('Lisa Zhou'!B15,'Colin Hui'!B15,'Iris Liu'!B15,'Max McCarter'!B15,'Member 5 Name'!B15,'Member 6 Name'!B15,'Member 7 Name'!B15)=0,0,COUNTA('Lisa Zhou'!B15,'Colin Hui'!B15,'Iris Liu'!B15,'Max McCarter'!B15,'Member 5 Name'!B15,'Member 6 Name'!B15,'Member 7 Name'!B15)) -> 4 | C15: =IF(COUNTA('Lisa Zhou'!C15,'Colin Hui'!C15,'Iris Liu'!C15,'Max McCarter'!C15,'Member 5 Name'!C15,'Member 6 Name'!C15,'Member 7 Name'!C15)=0,0,COUNTA('Lisa Zhou'!C15,'Colin Hui'!C15,'Iris Liu'!C15,'Max McCarter'!C15,'Member 5 Name'!C15,'Member 6 Name'!C15,'Member 7 Name'!C15)) -> 4 | D15: =IF(COUNTA('Lisa Zhou'!D15,'Colin Hui'!D15,'Iris Liu'!D15,'Max McCarter'!D15,'Member 5 Name'!D15,'Member 6 Name'!D15,'Member 7 Name'!D15)=0,0,COUNTA('Lisa Zhou'!D15,'Colin Hui'!D15,'Iris Liu'!D15,'Max McCarter'!D15,'Member 5 Name'!D15,'Member 6 Name'!D15,'Member 7 Name'!D15)) -> 4 | E15: =IF(COUNTA('Lisa Zhou'!E15,'Colin Hui'!E15,'Iris Liu'!E15,'Max McCarter'!E15,'Member 5 Name'!E15,'Member 6 Name'!E15,'Member 7 Name'!E15)=0,0,COUNTA('Lisa Zhou'!E15,'Colin Hui'!E15,'Iris Liu'!E15,'Max McCarter'!E15,'Member 5 Name'!E15,'Member 6 Name'!E15,'Member 7 Name'!E15)) -> 4 | F15: =IF(COUNTA('Lisa Zhou'!F15,'Colin Hui'!F15,'Iris Liu'!F15,'Max McCarter'!F15,'Member 5 Name'!F15,'Member 6 Name'!F15,'Member 7 Name'!F15)=0,0,COUNTA('Lisa Zhou'!F15,'Colin Hui'!F15,'Iris Liu'!F15,'Max McCarter'!F15,'Member 5 Name'!F15,'Member 6 Name'!F15,'Member 7 Name'!F15)) -> 4 | G15: =IF(COUNTA('Lisa Zhou'!G15,'Colin Hui'!G15,'Iris Liu'!G15,'Max McCarter'!G15,'Member 5 Name'!G15,'Member 6 Name'!G15,'Member 7 Name'!G15)=0,0,COUNTA('Lisa Zhou'!G15,'Colin Hui'!G15,'Iris Liu'!G15,'Max McCarter'!G15,'Member 5 Name'!G15,'Member 6 Name'!G15,'Member 7 Name'!G15)) -> 1 | H15: =IF(COUNTA('Lisa Zhou'!H15,'Colin Hui'!H15,'Iris Liu'!H15,'Max McCarter'!H15,'Member 5 Name'!H15,'Member 6 Name'!H15,'Member 7 Name'!H15)=0,0,COUNTA('Lisa Zhou'!H15,'Colin Hui'!H15,'Iris Liu'!H15,'Max McCarter'!H15,'Member 5 Name'!H15,'Member 6 Name'!H15,'Member 7 Name'!H15)) -> 1
